Workbook

Sheet Resumen
A1: GUAICARAMO S.A.S. – Auditoría de Obligaciones Financieras (cuenta 21 / papel 62) – corte 31-jul-2026
A2: Cruce movimiento ↔ detalle 62 ↔ certificados bancarios ↔ balance de prueba; recálculo de intereses (NIIF 9 costo amortizado, NIIF 16, NIC 1). Cifras en pesos colombianos. Azul = dato de la fuente; negro = fórmula; verde = vínculo a otra hoja; amarillo = cifra clave.
B4: Parámetros
B5: Fecha de corte | C5: 46234
B6: Umbral de diferencia trivial / redondeo (COP) | C6: 1000
B7: Tolerancia recálculo de intereses (%) | C7: 0.02
B9: Resultados por prueba
B10: Prueba | C10: Valor A | D10: Valor B | E10: Diferencia | F10: Estado
B11: 1. Integridad: movimiento auxiliar vs balance – SF cuenta 21 | C11: =Cruce_Mov_Balance!F12 -> -4.6662703e+10 | D11: =Cruce_Mov_Balance!G12 -> -4.6662703e+10 | E11: =C11-D11 -> 0 | F11: =IF(ABS(E11)<=$C$6,"OK","DIFERENCIA") -> OK
B12: 2. Integridad: balance 29-sep vs balance 24-ago – nº cuentas con diferencias | C12: =Balance_21!$C$40 -> 0 | D12: =0 -> 0 | E12: =C12-D12 -> 0 | F12: =IF(ABS(E12)<=$C$6,"OK","DIFERENCIA") -> OK
B13: 3. Detalle 62: suma recalculada vs 'Total obligaciones' del cliente | C13: =Detalle_62!F36 -> 4.5185912e+10 | D13: =Detalle_62!F37 -> 4.5185912e+10 | E13: =C13-D13 -> 0 | F13: =IF(ABS(E13)<=$C$6,"OK","DIFERENCIA") -> OK
B14: 4. Créditos: detalle 62 vs mayor (21050100 + 21050201) | C14: =Cruce_Detalle_Mayor!D6 -> 3.8300667e+10 | D14: =Cruce_Detalle_Mayor!E6 -> 38300666666 | E14: =C14-D14 -> -0.66666412 | F14: =IF(ABS(E14)<=$C$6,"OK","DIFERENCIA") -> OK
B15: 5. Leasing: detalle 62 vs mayor (21202040 + 21202140) | C15: =Cruce_Detalle_Mayor!D7 -> 6.8852455e+09 | D15: =Cruce_Detalle_Mayor!E7 -> 7.9035116e+09 | E15: =C15-D15 -> -1.0182662e+09 | F15: =IF(ABS(E15)<=$C$6,"OK","DIFERENCIA") -> DIFERENCIA
B16: 6. Certificados: capital banco 31-jul vs detalle 62 (obligaciones con saldo certificado) | C16: =SUMIFS(Certificados!J5:J21,Certificados!H5:H21,"<>") -> 3.5993167e+10 | D16: =SUMIFS(Certificados!K5:K21,Certificados!H5:H21,"<>") -> 3.5821568e+10 | E16: =C16-D16 -> 1.715997e+08 | F16: =IF(ABS(E16)<=$C$6,"OK","DIFERENCIA") -> DIFERENCIA
B17: 7. Certificados: pagos/intereses certificados vs registrados (comprobantes) | C17: =Certificados!H79 -> 3.3299172e+09 | D17: =Certificados!I79 -> 3.3418922e+09 | E17: =C17-D17 -> -11975072 | F17: =IF(ABS(E17)<=$C$6,"OK","DIFERENCIA") -> DIFERENCIA
B18: 8. Recálculo de intereses liquidados por el banco (Parte 1) | C18: =Recalculo_Intereses!J20+Recalculo_Intereses!K20 -> 1.561142e+09 | D18: =Recalculo_Intereses!J20 -> 1.6129345e+09 | E18: =C18-D18 -> -51792495 | F18: =IF(ABS(E18)<=$C$6,"OK","DIFERENCIA") -> DIFERENCIA
B19: 9. Intereses causados al 31-jul: recalculado vs registrado en 2130 | C19: =Recalculo_Intereses!I47 -> 6.1567279e+08 | D19: =Recalculo_Intereses!J47 -> 427389017 | E19: =C19-D19 -> 1.8828377e+08 | F19: =IF(ABS(E19)<=$C$6,"OK","DIFERENCIA") -> DIFERENCIA
B20: 10. Intereses por pagar: suma por obligación vs balance 2130 | C20: =Recalculo_Intereses!J47 -> 427389017 | D20: =-Balance_21!$F$25 -> 4.2738902e+08 | E20: =C20-D20 -> -0.16000003 | F20: =IF(ABS(E20)<=$C$6,"OK","DIFERENCIA") -> OK
B22: Indicadores clave
B23: Saldo de capital según mayor 31-jul (2105 sin TC + 2120) | C23: =Gasto_Intereses!B5 -> 4.6204178e+10
B24: Saldo según detalle 62 | C24: =Detalle_62!F36 -> 4.5185912e+10
B25: Leasing 386735 omitido en el detalle 62 | C25: =Cruce_Detalle_Mayor!F14 -> 675837500
B26: Leasings Bogotá: detalle por debajo de los certificados | C26: =Cruce_Detalle_Mayor!F15 -> 1.7160825e+08
B27: Diferencia de leasing sin explicar (requiere certificados) | C27: =Cruce_Detalle_Mayor!F16 -> 1.7082042e+08
B28: % del saldo del detalle 62 cubierto con certificados | C28: =Certificados!$K$35 -> 0.85042859
B29: Intereses no causados al 31-jul (AJE-1) | C29: =Recalculo_Intereses!K47 -> 1.8828377e+08
B30: Reclasificación LP → CP propuesta (créditos + leasing) | C30: =Clasif_CP_LP!B11+Clasif_CP_LP!B12 -> 2.8172851e+09
B31: Gasto de intereses: desviación vs expectativa | C31: =Gasto_Intereses!$B$18 -> -0.07111828
B32: Conclusión prueba analítica | C32: =Gasto_Intereses!$B$20 -> Gasto razonable dentro del umbral
B34: Conclusión
B35: INTEGRIDAD – Mayor vs balance: el movimiento auxiliar de la cuenta 21 cuadra exactamente (débitos, créditos y saldos) con los dos balances de prueba, que son idénticos entre sí. Sin excepción.
B36: INTEGRIDAD – Detalle 62 vs mayor: los créditos cuadran (diferencia de redondeo $0,67). El leasing NO cuadra: el mayor supera al detalle; la principal causa es el leasing Bancolombia 386735 omitido en el detalle.
B37: EXACTITUD – Certificados: los créditos cuadran con los extractos salvo redondeos de abonos a capital (< $5.000). Los leasings de Banco de Bogotá están subvalorados en el detalle 62. Los pagos registrados coinciden con los extractos, salvo el canon 032 del leasing 1019441.
B38: RECÁLCULO – La liquidación bancaria es razonable en base 365 (Bogotá Finagro en base 360), excepto Davivienda 607691/569032, cuya tasa declarada no reconcilia. Hay intereses causados no registrados al 31-jul (AJE-1) por la política de causación del cliente.
B39: PRESENTACIÓN – Se requiere reclasificar la porción corriente (NIC 1.69) y corregir los errores CP/LP del detalle 62. Ver la hoja 'Hallazgos'.
B41: Hojas del libro
B42: Mayor_Mov | C42: Movimiento auxiliar ene–jul con el ID de obligación asignado por auditoría
B43: Balance_21 | C43: Cuentas 21/5305 de ambos balances de prueba y su comparación
B44: Cruce_Mov_Balance | C44: Integridad: movimiento vs balance, jerarquía de cuentas y relación pasivo–gasto
B45: Detalle_62 | C45: Detalle del cliente con recálculo de tasas, subtotales y CP/LP
...

Sheet Mayor_Mov
A1: Movimiento auxiliar cuenta 21 – Obligaciones financieras (ene–jul 2026)
A2: Fuente: Obl_Financieros.xlsx / Sheet1 (Siesa). Columnas N–P asignadas por auditoría (ID de obligación, clase y tipo de movimiento).
A4: Fila origen | B4: Cuenta | C4: Nombre cuenta | D4: Tercero | E4: Débito | F4: Crédito | G4: Neto (D-C) | H4: Fecha | I4: NIT | J4: Documento | K4: Tipo documento | L4: Descripción | M4: Usuario | N4: ID obligación (auditoría) | O4: Clase | P4: Tipo movimiento
A5: 2 | B5: 21050100 | C5: Obl.Financiera Corto Plazo | D5: BANCO BILBAO VIZCAYA ARGENTARIA COLOMBIA S A PUDIENDO UTILIZAR INDISTINTAMENTE PARA TODOS LOS EFECTO | E5: 4700000000 | F5: 4700000000 | G5: =E5-F5 -> 0 | H5: 46203 | I5: 860003020 | J5: CE-00035090 | K5: Comprobante de Egreso | L5: RENOVACION CREDITO 0141 PLAZO 6 MESES - AMORTIZACION AL VENCIMIENTO -INTERESES MENSUALES - IBR + 1 EA 4.700.000.000 | M5: yan.lopez | N5: BBVA-0141 | O5: Capital crédito CP | P5: Renovación / prórroga
A6: 3 | B6: 21050100 | C6: Obl.Financiera Corto Plazo | D6: BANCO DAVIVIENDA S.A. | E6: 10000000000 | F6: 0 | G6: =E6-F6 -> 10000000000 | H6: 46050 | I6: 860002964 | J6: NB-00000892 | K6: Notas Bancarias | L6: PRESTAMO (1155297469) DE 10.000MM PARA PAGO CREDI 8906 DE DAVIVIENDA POR EL MISMO VALOR | M6: yan.lopez | N6: DAV-8906 | O6: Capital crédito CP | P6: Pago de capital
A7: 4 | B7: 21050100 | C7: Obl.Financiera Corto Plazo | D7: BANCO DE BOGOTA | E7: 0 | F7: 10000000000 | G7: =E7-F7 -> -10000000000 | H7: 46050 | I7: 860002964 | J7: NB-00000892 | K7: Notas Bancarias | L7: PRESTAMO (1155297469) DE 10.000MM PARA PAGO CREDI 8906 DE DAVIVIENDA POR EL MISMO VALOR | M7: yan.lopez | N7: BOG-1159383796 | O7: Capital crédito CP | P7: Desembolso / nueva obligación
A8: 5 | B8: 21050100 | C8: Obl.Financiera Corto Plazo | D8: BANCO DE BOGOTA | E8: 10000000000 | F8: 10000000000 | G8: =E8-F8 -> 0 | H8: 46232 | I8: 860002964 | J8: NB-00001016 | K8: Notas Bancarias | L8: PRORROGA CREDITO 7469 POR EL CREDITO 1159383796 IBR TM + 0.8 VENCIMIENTO 6 MESES | M8: yan.lopez | N8: BOG-1159383796 | O8: Capital crédito CP | P8: Renovación / prórroga
A9: 6 | B9: 21050201 | C9: Obg.Financiera Largo Plazo | D9: BANCO DE BOGOTA | E9: 62500000 | F9: 0 | G9: =E9-F9 -> 62500000 | H9: 46050 | I9: 860002964 | J9: CL-00000354 | K9: Causación Obligaciones Financieras | L9: CUOTA 94 CREDITO 453436746 MENSUAL CAPITAL 62.500.000 INTERESES 41.849.155.99 | M9: valentina.olea | N9: BOG-453436746 | O9: Capital crédito LP | P9: Pago de capital
A10: 7 | B10: 21050201 | C10: Obg.Financiera Largo Plazo | D10: BANCO DE BOGOTA | E10: 62500000 | F10: 0 | G10: =E10-F10 -> 62500000 | H10: 46071 | I10: 860002964 | J10: CL-00000371 | K10: Causación Obligaciones Financieras | L10: CANON 95 CREDITO 453436746 MES DE FEBRERO 2026 CAPITAL 62.500.000 INTERESES 36.701.211.58 | M10: valentina.olea | N10: BOG-453436746 | O10: Capital crédito LP | P10: Pago de capital
A11: 8 | B11: 21050201 | C11: Obg.Financiera Largo Plazo | D11: BANCO DE BOGOTA | E11: 125000000 | F11: 0 | G11: =E11-F11 -> 125000000 | H11: 46071 | I11: 860002964 | J11: CL-00000372 | K11: Causación Obligaciones Financieras | L11: CANON 10 CREDITO 858177259 TRIMESTRAL (DIC-ENE-FEB) GASTOS BANCARIOS 238 INTERESES 47.641.305.47 | M11: valentina.olea | N11: BOG-858177259 | O11: Capital crédito LP | P11: Pago de capital
A12: 9 | B12: 21050201 | C12: Obg.Financiera Largo Plazo | D12: BANCO DE BOGOTA | E12: 182166667 | F12: 0 | G12: =E12-F12 -> 182166667 | H12: 46100 | I12: 860002964 | J12: CL-00000383 | K12: Causación Obligaciones Financieras | L12: CUOTA 11 CREDITO 856670629 TRIMESTRAL (ENE-FEB-MAR) CAPITAL 182.166.667 INTERESES 56.089.116.47 GASTOS BANCARIOS 238 | M12: valentina.olea | N12: BOG-856670629 | O12: Capital crédito LP | P12: Pago de capital
A13: 10 | B13: 21050201 | C13: Obg.Financiera Largo Plazo | D13: BANCO DE BOGOTA | E13: 62500000 | F13: 0 | G13: =E13-F13 -> 62500000 | H13: 46100 | I13: 860002964 | J13: CL-00000384 | K13: Causación Obligaciones Financieras | L13: CANON 96 CREDITO 453436746 MENSUAL CAPITAL 62.500.000 INTERESES 36.314.055.32 | M13: valentina.olea | N13: BOG-453436746 | O13: Capital crédito LP | P13: Pago de capital
A14: 11 | B14: 21050201 | C14: Obg.Financiera Largo Plazo | D14: BANCO DE BOGOTA | E14: 62500000 | F14: 0 | G14: =E14-F14 -> 62500000 | H14: 46136 | I14: 860002964 | J14: CL-00000395 | K14: Causación Obligaciones Financieras | L14: CANON 97 CREDITO 453436746 MENSUAL CAPITAL 62.500.000 INTERESES 40.669.577.85 | M14: valentina.olea | N14: BOG-453436746 | O14: Capital crédito LP | P14: Pago de capital
A15: 12 | B15: 21050201 | C15: Obg.Financiera Largo Plazo | D15: BANCO DE BOGOTA | E15: 125000000 | F15: 0 | G15: =E15-F15 -> 125000000 | H15: 46164 | I15: 860002964 | J15: CL-00000407 | K15: Causación Obligaciones Financieras | L15: CANON 11 CREDITO 858177259 TRIMESTRAL | M15: valentina.olea | N15: BOG-858177259 | O15: Capital crédito LP | P15: Pago de capital
A16: 13 | B16: 21050201 | C16: Obg.Financiera Largo Plazo | D16: BANCO DE BOGOTA | E16: 62500000 | F16: 0 | G16: =E16-F16 -> 62500000 | H16: 46164 | I16: 860002964 | J16: CL-00000408 | K16: Causación Obligaciones Financieras | L16: CANON 98 CREDITO 453436746 MENSUAL | M16: valentina.olea | N16: BOG-453436746 | O16: Capital crédito LP | P16: Pago de capital
... A445: 442 | B445: 21300102 | C445: Intereses Leasing por Pagar | D445: BANCOLOMBIA S.A. | E445: 0 | F445: 3750337 | G445: =E445-F445 -> -3750337 | H445: 46227 | I445: 860040584 | J445: NB-00001013 | K445: Notas Bancarias | L445: INTERESES CAUSADOS JULIO LEAS 2095 JUL | M445: yan.lopez | N445: BCL-L362095 | O445: Interés leasing por pagar | P445: Causación
D446: TOTAL MOVIMIENTO | E446: =SUM(E5:E445) -> 3.2526204e+10 | F446: =SUM(F5:F445) -> 2.8526158e+10 | G446: =SUM(G5:G445) -> 4.0000458e+09

Sheet Balance_21
A1: Balances de prueba – cuentas 21, 5305 y totales de clase
A2: Fuentes: Obl_Financieros.xlsx/Hoja1 (emitido 29-sep-2026) y Balance_2026_GUUU.xlsx (emitido 24-ago-2026). Libro NIIF, cifras en pesos; saldos crédito con signo negativo.
C4: Balance 29-sep-2026 (Obl_Financieros/Hoja1) | G4: Balance 24-ago-2026 (Balance_2026_GUUU) | K4: Diferencias (29-sep menos 24-ago)
A5: Cuenta | B5: Descripción | C5: Saldo inicial 2026/01 | D5: Débitos | E5: Créditos | F5: Saldo final 2026/07 | G5: Saldo inicial 2026/01 | H5: Débitos | I5: Créditos | J5: Saldo final 2026/07 | K5: Dif. SI | L5: Dif. Déb. | M5: Dif. Créd. | N5: Dif. SF
A6: 1 | B6: ACTIVO | C6: 5.6755078e+11 | D6: 8.9276566e+11 | E6: 8.698483e+11 | F6: 5.9046814e+11 | G6: 5.6755078e+11 | H6: 8.9276566e+11 | I6: 8.698483e+11 | J6: 5.9046814e+11 | K6: =C6-G6 -> 0 | L6: =D6-H6 -> 0 | M6: =E6-I6 -> 0 | N6: =F6-J6 -> 0
A7: 2 | B7: PASIVOS | C7: -1.9109359e+11 | D7: 3.6225354e+11 | E7: 3.6857429e+11 | F7: -1.9741434e+11 | G7: -1.9109359e+11 | H7: 3.6225354e+11 | I7: 3.6857429e+11 | J7: -1.9741434e+11 | K7: =C7-G7 -> 0 | L7: =D7-H7 -> 0 | M7: =E7-I7 -> 0 | N7: =F7-J7 -> 0
A8: 3 | B8: PATRIMONIO | C8: -3.764572e+11 | D8: 7.3328495e+10 | E8: 7.1525661e+10 | F8: -3.7465436e+11 | G8: -3.764572e+11 | H8: 7.3328495e+10 | I8: 7.1525661e+10 | J8: -3.7465436e+11 | K8: =C8-G8 -> 0 | L8: =D8-H8 -> 0 | M8: =E8-I8 -> 0 | N8: =F8-J8 -> 0
A9: 4 | B9: INGRESOS | C9: 0 | D9: 3.2747697e+10 | E9: 2.0028385e+11 | F9: -1.6753616e+11 | G9: 0 | H9: 3.2747697e+10 | I9: 2.0028385e+11 | J9: -1.6753616e+11 | K9: =C9-G9 -> 0 | L9: =D9-H9 -> 0 | M9: =E9-I9 -> 0 | N9: =F9-J9 -> 0
A10: 5 | B10: GASTOS | C10: 0 | D10: 6.1606988e+10 | E10: 8.1995994e+09 | F10: 5.3407388e+10 | G10: 0 | H10: 6.1606988e+10 | I10: 8.1995994e+09 | J10: 5.3407388e+10 | K10: =C10-G10 -> 0 | L10: =D10-H10 -> 0 | M10: =E10-I10 -> 0 | N10: =F10-J10 -> 0
A11: 6 | B11: COSTOS DE VENTAS | C11: 0 | D11: 1.2631736e+11 | E11: 3.0588036e+10 | F11: 95729327632 | G11: 0 | H11: 1.2631736e+11 | I11: 3.0588036e+10 | J11: 95729327632 | K11: =C11-G11 -> 0 | L11: =D11-H11 -> 0 | M11: =E11-I11 -> 0 | N11: =F11-J11 -> 0
A12: 7 | B12: COSTO DE PRODUCCION O DE OPERACION | C12: 0 | D12: 2.8001381e+11 | E12: 2.8001381e+11 | F12: 0 | G12: 0 | H12: 2.8001381e+11 | I12: 2.8001381e+11 | J12: 0 | K12: =C12-G12 -> 0 | L12: =D12-H12 -> 0 | M12: =E12-I12 -> 0 | N12: =F12-J12 -> 0
A13: 21 | B13: OBLIGACIONES FINANCIERAS | C13: -5.0662749e+10 | D13: 3.2526204e+10 | E13: 2.8526158e+10 | F13: -4.6662703e+10 | G13: -5.0662749e+10 | H13: 3.2526204e+10 | I13: 2.8526158e+10 | J13: -4.6662703e+10 | K13: =C13-G13 -> 0 | L13: =D13-H13 -> 0 | M13: =E13-I13 -> 0 | N13: =F13-J13 -> 0
A14: 2105 | B14: OBLIGACIONES FINANCIERAS | C14: -4.1332031e+10 | D14: 2.7823936e+10 | E14: 2.4823707e+10 | F14: -3.8331802e+10 | G14: -4.1332031e+10 | H14: 2.7823936e+10 | I14: 2.4823707e+10 | J14: -3.8331802e+10 | K14: =C14-G14 -> 0 | L14: =D14-H14 -> 0 | M14: =E14-I14 -> 0 | N14: =F14-J14 -> 0
A15: 210501 | B15: Obligaciones Financieras a Corto Plazo | C15: -17938333333 | D15: 24700000000 | E15: 24700000000 | F15: -17938333333 | G15: -17938333333 | H15: 24700000000 | I15: 24700000000 | J15: -17938333333 | K15: =C15-G15 -> 0 | L15: =D15-H15 -> 0 | M15: =E15-I15 -> 0 | N15: =F15-J15 -> 0
A16: 21050100 | B16: Obl.Financiera Corto Plazo | C16: -17938333333 | D16: 24700000000 | E16: 24700000000 | F16: -17938333333 | G16: -17938333333 | H16: 24700000000 | I16: 24700000000 | J16: -17938333333 | K16: =C16-G16 -> 0 | L16: =D16-H16 -> 0 | M16: =E16-I16 -> 0 | N16: =F16-J16 -> 0
A17: 210502 | B17: Obligaciones Financieras a Largo Plazo | C17: -2.3393698e+10 | D17: 3.1239356e+09 | E17: 1.2370672e+08 | F17: -2.0393469e+10 | G17: -2.3393698e+10 | H17: 3.1239356e+09 | I17: 1.2370672e+08 | J17: -2.0393469e+10 | K17: =C17-G17 -> 0 | L17: =D17-H17 -> 0 | M17: =E17-I17 -> 0 | N17: =F17-J17 -> 0
... A36: 53052040 | B36: Intereses Leasing Causados | C36: 0 | D36: 502463085 | E36: 4.9871275e+08 | F36: 3750337.3 | G36: 0 | H36: 502463085 | I36: 4.9871275e+08 | J36: 3750337.3 | K36: =C36-G36 -> 0 | L36: =D36-H36 -> 0 | M36: =E36-I36 -> 0 | N36: =F36-J36 -> 0
A38: Comparación integral de las dos versiones del balance (todas las cuentas):
A39: Cuentas comparadas | C39: 1268
A40: Cuentas con alguna diferencia (SI, Déb., Créd. o SF) | C40: 0

Sheet Cruce_Mov_Balance
A1: Cruce movimiento auxiliar (cuenta 21) vs balance de prueba – Integridad
A2: SI balance + Débitos movimiento − Créditos movimiento = SF calculado; se compara con SF del balance. Signo: crédito negativo.
A4: Cuenta | B4: Descripción | C4: Saldo inicial balance | D4: Débitos movimiento | E4: Créditos movimiento | F4: SF calculado | G4: SF balance | H4: Diferencia SF | I4: Débitos balance | J4: Dif. débitos | K4: Créditos balance | L4: Dif. créditos | M4: Estado
A5: 21050100 | B5: =INDEX(Balance_21!$B$6:$B$36,MATCH(A5,Balance_21!$A$6:$A$36,0)) -> Obl.Financiera Corto Plazo | C5: =Balance_21!$C$16 -> -17938333333 | D5: =SUMIFS(Mayor_Mov!$E$5:$E$445,Mayor_Mov!$B$5:$B$445,A5) -> 24700000000 | E5: =SUMIFS(Mayor_Mov!$F$5:$F$445,Mayor_Mov!$B$5:$B$445,A5) -> 24700000000 | F5: =C5+D5-E5 -> -17938333333 | G5: =Balance_21!$F$16 -> -17938333333 | H5: =F5-G5 -> 0 | I5: =Balance_21!$D$16 -> 24700000000 | J5: =D5-I5 -> 0 | K5: =Balance_21!$E$16 -> 24700000000 | L5: =E5-K5 -> 0 | M5: =IF(MAX(ABS(H5),ABS(J5),ABS(L5))<=Resumen!$C$6,"OK","DIFERENCIA") -> OK
A6: 21050201 | B6: =INDEX(Balance_21!$B$6:$B$36,MATCH(A6,Balance_21!$A$6:$A$36,0)) -> Obg.Financiera Largo Plazo | C6: =Balance_21!$C$18 -> -23368333333 | D6: =SUMIFS(Mayor_Mov!$E$5:$E$445,Mayor_Mov!$B$5:$B$445,A6) -> 3006000000 | E6: =SUMIFS(Mayor_Mov!$F$5:$F$445,Mayor_Mov!$B$5:$B$445,A6) -> 0 | F6: =C6+D6-E6 -> -20362333333 | G6: =Balance_21!$F$18 -> -20362333333 | H6: =F6-G6 -> 0 | I6: =Balance_21!$D$18 -> 3006000000 | J6: =D6-I6 -> 0 | K6: =Balance_21!$E$18 -> 0 | L6: =E6-K6 -> 0 | M6: =IF(MAX(ABS(H6),ABS(J6),ABS(L6))<=Resumen!$C$6,"OK","DIFERENCIA") -> OK
A7: 21050301 | B7: =INDEX(Balance_21!$B$6:$B$36,MATCH(A7,Balance_21!$A$6:$A$36,0)) -> Tarjeta de Credito por Pagar | C7: =Balance_21!$C$19 -> -25364582 | D7: =SUMIFS(Mayor_Mov!$E$5:$E$445,Mayor_Mov!$B$5:$B$445,A7) -> 1.1793557e+08 | E7: =SUMIFS(Mayor_Mov!$F$5:$F$445,Mayor_Mov!$B$5:$B$445,A7) -> 1.2370672e+08 | F7: =C7+D7-E7 -> -31135732 | G7: =Balance_21!$F$19 -> -31135732 | H7: =F7-G7 -> 0 | I7: =Balance_21!$D$19 -> 1.1793557e+08 | J7: =D7-I7 -> 0 | K7: =Balance_21!$E$19 -> 1.2370672e+08 | L7: =E7-K7 -> 0 | M7: =IF(MAX(ABS(H7),ABS(J7),ABS(L7))<=Resumen!$C$6,"OK","DIFERENCIA") -> OK
A8: 21202040 | B8: =INDEX(Balance_21!$B$6:$B$36,MATCH(A8,Balance_21!$A$6:$A$36,0)) -> Leasing Corto Plazo | C8: =Balance_21!$C$22 -> -5.8588019e+08 | D8: =SUMIFS(Mayor_Mov!$E$5:$E$445,Mayor_Mov!$B$5:$B$445,A8) -> 35428634 | E8: =SUMIFS(Mayor_Mov!$F$5:$F$445,Mayor_Mov!$B$5:$B$445,A8) -> 607791830 | F8: =C8+D8-E8 -> -1.1582434e+09 | G8: =Balance_21!$F$22 -> -1.1582434e+09 | H8: =F8-G8 -> 0 | I8: =Balance_21!$D$22 -> 35428634 | J8: =D8-I8 -> 0 | K8: =Balance_21!$E$22 -> 607791830 | L8: =E8-K8 -> 0 | M8: =IF(MAX(ABS(H8),ABS(J8),ABS(L8))<=Resumen!$C$6,"OK","DIFERENCIA") -> OK
A9: 21202140 | B9: =INDEX(Balance_21!$B$6:$B$36,MATCH(A9,Balance_21!$A$6:$A$36,0)) -> Leasing Largo Plazo | C9: =Balance_21!$C$24 -> -7.5446146e+09 | D9: =SUMIFS(Mayor_Mov!$E$5:$E$445,Mayor_Mov!$B$5:$B$445,A9) -> 9.110819e+08 | E9: =SUMIFS(Mayor_Mov!$F$5:$F$445,Mayor_Mov!$B$5:$B$445,A9) -> 111735587 | F9: =C9+D9-E9 -> -6.7452682e+09 | G9: =Balance_21!$F$24 -> -6.7452682e+09 | H9: =F9-G9 -> 0 | I9: =Balance_21!$D$24 -> 9.110819e+08 | J9: =D9-I9 -> 0 | K9: =Balance_21!$E$24 -> 111735587 | L9: =E9-K9 -> 0 | M9: =IF(MAX(ABS(H9),ABS(J9),ABS(L9))<=Resumen!$C$6,"OK","DIFERENCIA") -> OK
A10: 21300101 | B10: =INDEX(Balance_21!$B$6:$B$36,MATCH(A10,Balance_21!$A$6:$A$36,0)) -> Intereses Financieros por Pagar O.F. | C10: =Balance_21!$C$27 -> -1107168370 | D10: =SUMIFS(Mayor_Mov!$E$5:$E$445,Mayor_Mov!$B$5:$B$445,A10) -> 3257045166 | E10: =SUMIFS(Mayor_Mov!$F$5:$F$445,Mayor_Mov!$B$5:$B$445,A10) -> 2573515476 | F10: =C10+D10-E10 -> -423638680 | G10: =Balance_21!$F$27 -> -423638680 | H10: =F10-G10 -> 0 | I10: =Balance_21!$D$27 -> 3257045166 | J10: =D10-I10 -> 0 | K10: =Balance_21!$E$27 -> 2573515476 | L10: =E10-K10 -> 0 | M10: =IF(MAX(ABS(H10),ABS(J10),ABS(L10))<=Resumen!$C$6,"OK","DIFERENCIA") -> OK
A11: 21300102 | B11: =INDEX(Balance_21!$B$6:$B$36,MATCH(A11,Balance_21!$A$6:$A$36,0)) -> Intereses Leasing por Pagar | C11: =Balance_21!$C$28 -> -93054514 | D11: =SUMIFS(Mayor_Mov!$E$5:$E$445,Mayor_Mov!$B$5:$B$445,A11) -> 4.9871275e+08 | E11: =SUMIFS(Mayor_Mov!$F$5:$F$445,Mayor_Mov!$B$5:$B$445,A11) -> 409408571 | F11: =C11+D11-E11 -> -3750337.2 | G11: =Balance_21!$F$28 -> -3750337.2 | H11: =F11-G11 -> -2.6077032e-08 | I11: =Balance_21!$D$28 -> 4.9871275e+08 | J11: =D11-I11 -> 0 | K11: =Balance_21!$E$28 -> 409408571 | L11: =E11-K11 -> 0 | M11: =IF(MAX(ABS(H11),ABS(J11),ABS(L11))<=Resumen!$C$6,"OK","DIFERENCIA") -> OK
B12: TOTAL CUENTA 21 | C12: =SUM(C5:C11) -> -5.0662749e+10 | D12: =SUM(D5:D11) -> 3.2526204e+10 | E12: =SUM(E5:E11) -> 2.8526158e+10 | F12: =SUM(F5:F11) -> -4.6662703e+10 | G12: =SUM(G5:G11) -> -4.6662703e+10 | H12: =SUM(H5:H11) -> -2.6077032e-08 | I12: =SUM(I5:I11) -> 3.2526204e+10 | J12: =SUM(J5:J11) -> 0 | ... L12: =SUM(L5:L11) -> 0 | M12: =IF(MAX(ABS(H12),ABS(J12),ABS(L12))<=Resumen!$C$6,"OK","DIFERENCIA") -> OK
B13: Total cuenta 21 según balance (mayor) | C13: =Balance_21!$C$13 -> -5.0662749e+10 | G13: =Balance_21!$F$13 -> -4.6662703e+10 | I13: =Balance_21!$D$13 -> 3.2526204e+10 | K13: =Balance_21!$E$13 -> 2.8526158e+10
B14: Diferencia suma de auxiliares vs cuenta 21 | C14: =C12-C13 -> 0 | G14: =G12-G13 -> 0 | I14: =I12-I13 -> 0 | K14: =K12-K13 -> 0
A16: B. Integridad del archivo de movimiento ('Gran total' del reporte vs suma de líneas)
B17: Concepto | C17: Gran total reporte | D17: Suma líneas | E17: Diferencia
B18: Débitos | C18: 3.2526204e+10 | D18: =Mayor_Mov!E446 -> 3.2526204e+10 | E18: =C18-D18 -> 0
B19: Créditos | C19: 2.8526158e+10 | D19: =Mayor_Mov!F446 -> 2.8526158e+10 | E19: =C19-D19 -> 0
B20: Neto | C20: 4.0000458e+09 | D20: =Mayor_Mov!G446 -> 4.0000458e+09 | E20: =C20-D20 -> 0
B21: Nº de líneas del movimiento | D21: =COUNTA(Mayor_Mov!$B$5:$B$445) -> 441
A23: C. Consistencia jerárquica del balance y relación pasivo–gasto
B24: Prueba | C24: Valor A | D24: Valor B | E24: Diferencia | G24: Comentario
B25: SF 21 = 2105 + 2120 + 2130 | C25: =Balance_21!$F$13 -> -4.6662703e+10 | D25: =Balance_21!$F$14+Balance_21!$F$20+Balance_21!$F$25 -> -4.6662703e+10 | E25: =C25-D25 -> 0
B26: SF 2105 = 210501 + 210502 | C26: =Balance_21!$F$14 -> -3.8331802e+10 | D26: =Balance_21!$F$15+Balance_21!$F$17 -> -3.8331802e+10 | E26: =C26-D26 -> 0
B27: SF 210502 = 21050201 + 21050301 (tarjeta de crédito agrupada en LP) | C27: =Balance_21!$F$17 -> -2.0393469e+10 | D27: =Balance_21!$F$18+Balance_21!$F$19 -> -2.0393469e+10 | E27: =C27-D27 -> 0 | G27: Tarjeta de crédito (pasivo corriente) agrupada dentro de 'Obligaciones financieras a largo plazo' – ver hallazgo de clasificación.
B28: SF 2120 = 21202040 + 21202140 | C28: =Balance_21!$F$20 -> -7.9035116e+09 | D28: =Balance_21!$F$22+Balance_21!$F$24 -> -7.9035116e+09 | E28: =C28-D28 -> 0
B29: SF 2130 = 21300101 + 21300102 | C29: =Balance_21!$F$25 -> -4.2738902e+08 | D29: =Balance_21!$F$27+Balance_21!$F$28 -> -4.2738902e+08 | E29: =C29-D29 -> 0
B30: Ecuación: Activo + Pasivo + Patrimonio + Resultado (4+5+6+7) = 0 | C30: =Balance_21!$F$6+Balance_21!$F$7+Balance_21!$F$8 -> 1.8399439e+10 | D30: =-(Balance_21!$F$9+Balance_21!$F$10+Balance_21!$F$11+Balance_21!$F$12) -> 1.8399439e+10 | E30: =C30-D30 -> 0 | G30: Resultado del periodo ene–jul incluido vía clases 4 a 7.
B31: Intereses OF por pagar (21300101) = gasto causado neto (53052030) | C31: =-Balance_21!$F$27 -> 423638680 | D31: =Balance_21!$F$35 -> 423638680 | E31: =C31-D31 -> 0 | G31: El cliente reversa la causación al pagar y lleva el pago a 53052020; el saldo de 53052030 debe igualar el pasivo.
B32: Intereses leasing por pagar (21300102) = gasto causado neto (53052040) | C32: =-Balance_21!$F$28 -> 3750337.2 | D32: =Balance_21!$F$36 -> 3750337.3 | E32: =C32-D32 -> -0.16
B33: SI 21300101 = créditos 53052020 (reclasificación apertura) | C33: =-Balance_21!$C$27 -> 1107168370 | D33: =Balance_21!$E$34 -> 1107168370 | E33: =C33-D33 -> 0 | G33: Asiento de apertura: Db 53052030 / Cr 53052020 por el saldo inicial causado.
B34: SI 21300102 = créditos 53052010 (reclasificación apertura) | C34: =-Balance_21!$C$28 -> 93054514 | D34: =Balance_21!$E$33 -> 93054514 | E34: =C34-D34 -> 0
A36: D. Comparación de versiones del balance
B37: Cuentas con diferencias entre balance 24-ago y 29-sep | C37: =Balance_21!$C$40 -> 0 | D37: =IF(C37=0,"Sin cambios posteriores al cierre de jul-26","Revisar ajustes posteriores") -> Sin cambios posteriores al cierre de jul-26

Sheet Detalle_62
A1: Detalle de obligaciones financieras del cliente (papel 62) a 31-jul-2026 – recálculo
A2: Fuente: 62._Obligaciones_Financieras.xlsx. Columnas A–Q: datos del cliente (azul). Columnas R en adelante: recálculo de auditoría.
A4: Tasas de referencia 31-jul-26 (cliente)
A5: IBR | B5: 0.11555
A6: IBR 3 MESES | B6: 0.11768
A7: IBR 6 MESES | B7: 0.12025
A8: DTF | B8: 0.1024
A9: SOFR | B9: 0.0362541
A10: TRM | B10: 3132.42
A13: Banco | B13: Nº obligación (cliente) | C13: ID auditoría | D13: Tipo | E13: Descripción | F13: Saldo deuda jul-26 | G13: % deuda (cliente) | H13: Tipo tasa | I13: Puntos adic. | J13: Tasa EA cliente | K13: Veces año | L13: Tipo pago | M13: Corto plazo (cliente) | N13: Largo plazo (cliente) | O13: Cuotas rest. | P13: Vencimiento | Q13: Tasa pond. cliente | R13: Índice aplicado | S13: Tasa EA recalculada | T13: Dif. EA (pb) | U13: CP + LP − Saldo | V13: Estado CP/LP | W13: CP corregido | X13: LP corregido | Y13: % deuda recalc.
A14: BANCO DAVIVIENDA | B14: LEASING 1019441 | C14: DAV-L1019441 | D14: Leasing | E14: CAMION LZT 927 | F14: 3.9858217e+08 | G14: 0.023355577 | H14: IBR | I14: 0.04 | J14: 0.16713318 | K14: 12 | L14: MENSUAL | M14: 194846536 | N14: 2.0373563e+08 | O14: 27 | P14: 47037 | Q14: 0.0039034919 | R14: =IF(LEFT(H14,11)="IBR 6 MESES",Detalle_62!$B$7,IF(LEFT(H14,11)="IBR 3 MESES",Detalle_62!$B$6,IF(H14="DTF",Detalle_62!$B$8,Detalle_62!$B$5))) -> 0.11555 | S14: =(1+(R14+I14)/K14)^K14-1 -> 0.16713318 | T14: =(J14-S14)*10000 -> 0 | U14: =M14+N14-F14 -> 0 | V14: =IF(ABS(U14)>Resumen!$C$6,"ERROR",IF(OR(M14<0,N14<0),"ERROR","OK")) -> OK | W14: =MIN(MAX(M14,0),F14) -> 194846536 | X14: =F14-W14 -> 2.0373563e+08 | Y14: =F14/SUMIFS($F$14:$F$35,$A$14:$A$35,A14) -> 0.023355577
A15: BANCO DAVIVIENDA | B15: LEASING 1019448 | C15: DAV-L1019448 | D15: Leasing | E15: CAMION LZT 926 | F15: 3.2352969e+08 | G15: 0.018957754 | H15: IBR | I15: 0.04 | J15: 0.16713318 | K15: 12 | L15: MENSUAL | M15: 1.4201465e+08 | N15: 1.8151504e+08 | O15: 29 | P15: 47098 | Q15: 0.0031684697 | R15: =IF(LEFT(H15,11)="IBR 6 MESES",Detalle_62!$B$7,IF(LEFT(H15,11)="IBR 3 MESES",Detalle_62!$B$6,IF(H15="DTF",Detalle_62!$B$8,Detalle_62!$B$5))) -> 0.11555 | S15: =(1+(R15+I15)/K15)^K15-1 -> 0.16713318 | T15: =(J15-S15)*10000 -> 0 | U15: =M15+N15-F15 -> 0 | V15: =IF(ABS(U15)>Resumen!$C$6,"ERROR",IF(OR(M15<0,N15<0),"ERROR","OK")) -> OK | W15: =MIN(MAX(M15,0),F15) -> 1.4201465e+08 | X15: =F15-W15 -> 1.8151504e+08 | Y15: =F15/SUMIFS($F$14:$F$35,$A$14:$A$35,A15) -> 0.018957754
A16: BANCO DAVIVIENDA | B16: LEASING 10212753 | C16: DAV-L1021275 | D16: Leasing | E16: CALDERAS-SISTEMA DE ALIMENTACION BIOMASA | F16: 1.8837122e+09 | G16: 0.11037921 | H16: IBR 3 MESES | I16: 0.023 | J16: 0.14827711 | K16: 4 | L16: TRIMESTRAL | M16: 0 | N16: 1.8837122e+09 | O16: 22 | P16: 48235 | Q16: 0.016366711 | R16: =IF(LEFT(H16,11)="IBR 6 MESES",Detalle_62!$B$7,IF(LEFT(H16,11)="IBR 3 MESES",Detalle_62!$B$6,IF(H16="DTF",Detalle_62!$B$8,Detalle_62!$B$5))) -> 0.11768 | S16: =(1+(R16+I16)/K16)^K16-1 -> 0.14827711 | T16: =(J16-S16)*10000 -> 0 | U16: =M16+N16-F16 -> 0 | V16: =IF(ABS(U16)>Resumen!$C$6,"ERROR",IF(OR(M16<0,N16<0),"ERROR","OK")) -> OK | W16: =MIN(MAX(M16,0),F16) -> 0 | X16: =F16-W16 -> 1.8837122e+09 | Y16: =F16/SUMIFS($F$14:$F$35,$A$14:$A$35,A16) -> 0.11037921
A17: BANCO DAVIVIENDA | B17: 457300569032 | C17: DAV-569032 | D17: Crédito | E17: CRED TESORERIA | F17: 3000000000 | G17: 0.17578993 | H17: IBR 6 MESES | I17: 0.034 | J17: 0.16019827 | K17: 2 | L17: SEMESTRAL | M17: 0 | N17: 3000000000 | O17: 30 | P17: 51710 | Q17: 0.028161242 | R17: =IF(LEFT(H17,11)="IBR 6 MESES",Detalle_62!$B$7,IF(LEFT(H17,11)="IBR 3 MESES",Detalle_62!$B$6,IF(H17="DTF",Detalle_62!$B$8,Detalle_62!$B$5))) -> 0.12025 | S17: =(1+(R17+I17)/K17)^K17-1 -> 0.16019827 | T17: =(J17-S17)*10000 -> 0 | U17: =M17+N17-F17 -> 0 | V17: =IF(ABS(U17)>Resumen!$C$6,"ERROR",IF(OR(M17<0,N17<0),"ERROR","OK")) -> OK | W17: =MIN(MAX(M17,0),F17) -> 0 | X17: =F17-W17 -> 3000000000 | Y17: =F17/SUMIFS($F$14:$F$35,$A$14:$A$35,A17) -> 0.17578993
A18: BANCO DAVIVIENDA | B18: 457300830624 | C18: DAV-830624 | D18: Crédito | E18: CRED TESORERIA | F18: 7500000000 | G18: 0.43947482 | H18: IBR 6 MESES | I18: 0.03 | J18: 0.15589377 | K18: 2 | L18: SEMESTRAL | M18: 0 | N18: 7500000000 | O18: 36 | P18: 52677 | Q18: 0.068511385 | R18: =IF(LEFT(H18,11)="IBR 6 MESES",Detalle_62!$B$7,IF(LEFT(H18,11)="IBR 3 MESES",Detalle_62!$B$6,IF(H18="DTF",Detalle_62!$B$8,Detalle_62!$B$5))) -> 0.12025 | S18: =(1+(R18+I18)/K18)^K18-1 -> 0.15589377 | T18: =(J18-S18)*10000 -> 0 | U18: =M18+N18-F18 -> 0 | V18: =IF(ABS(U18)>Resumen!$C$6,"ERROR",IF(OR(M18<0,N18<0),"ERROR","OK")) -> OK | W18: =MIN(MAX(M18,0),F18) -> 0 | X18: =F18-W18 -> 7500000000 | Y18: =F18/SUMIFS($F$14:$F$35,$A$14:$A$35,A18) -> 0.43947482
A19: BANCO DAVIVIENDA | B19: 457300607691 | C19: DAV-607691 | D19: Crédito | E19: CRED TESORERIA | F19: 3960000000 | G19: 0.23204271 | H19: IBR 6 MESES | I19: 0.034 | J19: 0.16019827 | K19: 2 | L19: SEMESTRAL | M19: 0 | N19: 3960000000 | O19: 30 | P19: 51710 | Q19: 0.037172839 | R19: =IF(LEFT(H19,11)="IBR 6 MESES",Detalle_62!$B$7,IF(LEFT(H19,11)="IBR 3 MESES",Detalle_62!$B$6,IF(H19="DTF",Detalle_62!$B$8,Detalle_62!$B$5))) -> 0.12025 | S19: =(1+(R19+I19)/K19)^K19-1 -> 0.16019827 | T19: =(J19-S19)*10000 -> 0 | U19: =M19+N19-F19 -> 0 | V19: =IF(ABS(U19)>Resumen!$C$6,"ERROR",IF(OR(M19<0,N19<0),"ERROR","OK")) -> OK | W19: =MIN(MAX(M19,0),F19) -> 0 | X19: =F19-W19 -> 3960000000 | Y19: =F19/SUMIFS($F$14:$F$35,$A$14:$A$35,A19) -> 0.23204271
A20: BANCO DE BOGOTA | B20: 453436746 | C20: BOG-453436746 | D20: Crédito | E20: CRED TESORERIA | F20: 2937500000 | G20: 0.16293886 | H20: IBR | I20: 0.047 | J20: 0.17522416 | K20: 12 | L20: MENSUAL | M20: 750000000 | N20: 2187500000 | O20: 47 | P20: 47651 | Q20: 0.028550826 | R20: =IF(LEFT(H20,11)="IBR 6 MESES",Detalle_62!$B$7,IF(LEFT(H20,11)="IBR 3 MESES",Detalle_62!$B$6,IF(H20="DTF",Detalle_62!$B$8,Detalle_62!$B$5))) -> 0.11555 | S20: =(1+(R20+I20)/K20)^K20-1 -> 0.17522416 | T20: =(J20-S20)*10000 -> 0 | U20: =M20+N20-F20 -> 0 | V20: =IF(ABS(U20)>Resumen!$C$6,"ERROR",IF(OR(M20<0,N20<0),"ERROR","OK")) -> OK | W20: =MIN(MAX(M20,0),F20) -> 750000000 | X20: =F20-W20 -> 2187500000 | Y20: =F20/SUMIFS($F$14:$F$35,$A$14:$A$35,A20) -> 0.16293886
A21: BANCO DE BOGOTA | B21: 856670629 | C21: BOG-856670629 | D21: Crédito | E21: CRED TESORERIA | F21: 1457333332 | G21: 0.080836166 | H21: IBR 3 MESES | I21: 0.032 | J21: 0.15829309 | K21: 4 | L21: TRIMESTRAL | M21: 750000000 | N21: 707333332 | O21: 8 | P21: 46925 | Q21: 0.012795806 | R21: =IF(LEFT(H21,11)="IBR 6 MESES",Detalle_62!$B$7,IF(LEFT(H21,11)="IBR 3 MESES",Detalle_62!$B$6,IF(H21="DTF",Detalle_62!$B$8,Detalle_62!$B$5))) -> 0.11768 | S21: =(1+(R21+I21)/K21)^K21-1 -> 0.15829309 | T21: =(J21-S21)*10000 -> 0 | U21: =M21+N21-F21 -> 0 | V21: =IF(ABS(U21)>Resumen!$C$6,"ERROR",IF(OR(M21<0,N21<0),"ERROR","OK")) -> OK | W21: =MIN(MAX(M21,0),F21) -> 750000000 | X21: =F21-W21 -> 707333332 | Y21: =F21/SUMIFS($F$14:$F$35,$A$14:$A$35,A21) -> 0.080836166
A22: BANCO DE BOGOTA | B22: 858177259 | C22: BOG-858177259 | D22: Crédito | E22: CRED TESORERIA | F22: 1125000000 | G22: 0.062402118 | H22: IBR 3 MESES | I22: 0.046 | J22: 0.17400356 | K22: 4 | L22: TRIMESTRAL | M22: 500000000 | N22: 625000000 | O22: 9 | P22: 46990 | Q22: 0.01085819 | R22: =IF(LEFT(H22,11)="IBR 6 MESES",Detalle_62!$B$7,IF(LEFT(H22,11)="IBR 3 MESES",Detalle_62!$B$6,IF(H22="DTF",Detalle_62!$B$8,Detalle_62!$B$5))) -> 0.11768 | S22: =(1+(R22+I22)/K22)^K22-1 -> 0.17400356 | T22: =(J22-S22)*10000 -> 0 | U22: =M22+N22-F22 -> 0 | V22: =IF(ABS(U22)>Resumen!$C$6,"ERROR",IF(OR(M22<0,N22<0),"ERROR","OK")) -> OK | W22: =MIN(MAX(M22,0),F22) -> 500000000 | X22: =F22-W22 -> 625000000 | Y22: =F22/SUMIFS($F$14:$F$35,$A$14:$A$35,A22) -> 0.062402118
A23: BANCO DE BOGOTA | B23: 1159383796 | C23: BOG-1159383796 | D23: Crédito | E23: CRED TESORERIA | F23: 10000000000 | G23: 0.5546855 | H23: IBR 3 MESES | I23: 0.008 | J23: 0.12962887 | K23: 2 | L23: SEMESTRAL | M23: 10000000000 | N23: 0 | O23: 1 | P23: 46409 | Q23: 0.071903251 | R23: =IF(LEFT(H23,11)="IBR 6 MESES",Detalle_62!$B$7,IF(LEFT(H23,11)="IBR 3 MESES",Detalle_62!$B$6,IF(H23="DTF",Detalle_62!$B$8,Detalle_62!$B$5))) -> 0.11768 | S23: =(1+(R23+I23)/K23)^K23-1 -> 0.12962887 | T23: =(J23-S23)*10000 -> 0 | U23: =M23+N23-F23 -> 0 | V23: =IF(ABS(U23)>Resumen!$C$6,"ERROR",IF(OR(M23<0,N23<0),"ERROR","OK")) -> OK | W23: =MIN(MAX(M23,0),F23) -> 10000000000 | X23: =F23-W23 -> 0 | Y23: =F23/SUMIFS($F$14:$F$35,$A$14:$A$35,A23) -> 0.5546855
A24: BANCO DE BOGOTA | B24: LEASING 556449224 | C24: BOG-L556449224 | D24: Leasing | E24: POZO # 1 | F24: 3.8184539e+08 | G24: 0.02118041 | H24: DTF | I24: 0.0357 | J24: 0.14541789 | K24: 4 | L24: TRIMESTRAL | M24: 1.7563157e+08 | N24: 2.0621382e+08 | O24: 14 | P24: 47503 | Q24: 0.0030800104 | R24: =IF(LEFT(H24,11)="IBR 6 MESES",Detalle_62!$B$7,IF(LEFT(H24,11)="IBR 3 MESES",Detalle_62!$B$6,IF(H24="DTF",Detalle_62!$B$8,Detalle_62!$B$5))) -> 0.1024 | S24: =(1+(R24+I24)/K24)^K24-1 -> 0.14541789 | T24: =(J24-S24)*10000 -> 0 | U24: =M24+N24-F24 -> 0 | V24: =IF(ABS(U24)>Resumen!$C$6,"ERROR",IF(OR(M24<0,N24<0),"ERROR","OK")) -> OK | W24: =MIN(MAX(M24,0),F24) -> 1.7563157e+08 | X24: =F24-W24 -> 2.0621382e+08 | Y24: =F24/SUMIFS($F$14:$F$35,$A$14:$A$35,A24) -> 0.02118041
A25: BANCO DE BOGOTA | B25: LEASING 556449180 | C25: BOG-L556449180 | D25: Leasing | E25: POZO # 2 | F25: 3.8184539e+08 | G25: 0.02118041 | H25: DTF | I25: 0.0357 | J25: 0.14541789 | K25: 4 | L25: TRIMESTRAL | M25: 1.7563157e+08 | N25: 4.5915438e+08 | O25: 14 | P25: 47503 | Q25: 0.0030800104 | R25: =IF(LEFT(H25,11)="IBR 6 MESES",Detalle_62!$B$7,IF(LEFT(H25,11)="IBR 3 MESES",Detalle_62!$B$6,IF(H25="DTF",Detalle_62!$B$8,Detalle_62!$B$5))) -> 0.1024 | S25: =(1+(R25+I25)/K25)^K25-1 -> 0.14541789 | T25: =(J25-S25)*10000 -> 0 | U25: =M25+N25-F25 -> 2.5294057e+08 | V25: =IF(ABS(U25)>Resumen!$C$6,"ERROR",IF(OR(M25<0,N25<0),"ERROR","OK")) -> ERROR | W25: =MIN(MAX(M25,0),F25) -> 1.7563157e+08 | X25: =F25-W25 -> 2.0621382e+08 | Y25: =F25/SUMIFS($F$14:$F$35,$A$14:$A$35,A25) -> 0.02118041
A26: BANCO DE BOGOTA | B26: LEASING 556449117 | C26: BOG-L556449117 | D26: Leasing | E26: POZO # 3 | F26: 1.9672018e+08 | G26: 0.010911783 | H26: DTF | I26: 0.0357 | J26: 0.14541789 | K26: 4 | L26: TRIMESTRAL | M26: 1.7563157e+08 | N26: 21088609 | O26: 8 | P26: 46870 | Q26: 0.0015867684 | R26: =IF(LEFT(H26,11)="IBR 6 MESES",Detalle_62!$B$7,IF(LEFT(H26,11)="IBR 3 MESES",Detalle_62!$B$6,IF(H26="DTF",Detalle_62!$B$8,Detalle_62!$B$5))) -> 0.1024 | S26: =(1+(R26+I26)/K26)^K26-1 -> 0.14541789 | T26: =(J26-S26)*10000 -> 0 | U26: =M26+N26-F26 -> 0 | V26: =IF(ABS(U26)>Resumen!$C$6,"ERROR",IF(OR(M26<0,N26<0),"ERROR","OK")) -> OK | W26: =MIN(MAX(M26,0),F26) -> 1.7563157e+08 | X26: =F26-W26 -> 21088609 | Y26: =F26/SUMIFS($F$14:$F$35,$A$14:$A$35,A26) -> 0.010911783
A27: BANCO DE BOGOTA | B27: LEASING 556449064 | C27: BOG-L556449064 | D27: Leasing | E27: POZO # 4 | F27: 1.9672018e+08 | G27: 0.010911783 | H27: DTF | I27: 0.0357 | J27: 0.14541789 | K27: 4 | L27: TRIMESTRAL | M27: 1.7563157e+08 | N27: 21088609 | O27: 8 | P27: 46870 | Q27: 0.0015867684 | R27: =IF(LEFT(H27,11)="IBR 6 MESES",Detalle_62!$B$7,IF(LEFT(H27,11)="IBR 3 MESES",Detalle_62!$B$6,IF(H27="DTF",Detalle_62!$B$8,Detalle_62!$B$5))) -> 0.1024 | S27: =(1+(R27+I27)/K27)^K27-1 -> 0.14541789 | T27: =(J27-S27)*10000 -> 0 | U27: =M27+N27-F27 -> 0 | V27: =IF(ABS(U27)>Resumen!$C$6,"ERROR",IF(OR(M27<0,N27<0),"ERROR","OK")) -> OK | W27: =MIN(MAX(M27,0),F27) -> 1.7563157e+08 | X27: =F27-W27 -> 21088609 | Y27: =F27/SUMIFS($F$14:$F$35,$A$14:$A$35,A27) -> 0.010911783
A28: BANCO DE BOGOTA | B28: LEASING 556449288 | C28: BOG-L556449288 | D28: Leasing | E28: POZO # 5 | F28: 3.8264924e+08 | G28: 0.021224998 | H28: DTF | I28: 0.0357 | J28: 0.14541789 | K28: 4 | L28: TRIMESTRAL | M28: 1.7563157e+08 | N28: 2.0701767e+08 | O28: 14 | P28: 47503 | Q28: 0.0030864944 | R28: =IF(LEFT(H28,11)="IBR 6 MESES",Detalle_62!$B$7,IF(LEFT(H28,11)="IBR 3 MESES",Detalle_62!$B$6,IF(H28="DTF",Detalle_62!$B$8,Detalle_62!$B$5))) -> 0.1024 | S28: =(1+(R28+I28)/K28)^K28-1 -> 0.14541789 | T28: =(J28-S28)*10000 -> 0 | U28: =M28+N28-F28 -> 0 | V28: =IF(ABS(U28)>Resumen!$C$6,"ERROR",IF(OR(M28<0,N28<0),"ERROR","OK")) -> OK | W28: =MIN(MAX(M28,0),F28) -> 1.7563157e+08 | X28: =F28-W28 -> 2.0701767e+08 | Y28: =F28/SUMIFS($F$14:$F$35,$A$14:$A$35,A28) -> 0.021224998
A29: BANCO DE BOGOTA | B29: LEASING 557285005 | C29: BOG-L557285005 | D29: Leasing | E29: PLANTA ELECTRICA JENBACHER | F29: 9.6862047e+08 | G29: 0.053727973 | H29: IBR 3 MESES | I29: 0.0378 | J29: 0.16478246 | K29: 4 | L29: TRIMESTRAL | M29: 722980190 | N29: 2.4564028e+08 | O29: 12 | P29: 47321 | Q29: 0.0088534272 | R29: =IF(LEFT(H29,11)="IBR 6 MESES",Detalle_62!$B$7,IF(LEFT(H29,11)="IBR 3 MESES",Detalle_62!$B$6,IF(H29="DTF",Detalle_62!$B$8,Detalle_62!$B$5))) -> 0.11768 | S29: =(1+(R29+I29)/K29)^K29-1 -> 0.16478246 | T29: =(J29-S29)*10000 -> 0 | U29: =M29+N29-F29 -> 0 | V29: =IF(ABS(U29)>Resumen!$C$6,"ERROR",IF(OR(M29<0,N29<0),"ERROR","OK")) -> OK | W29: =MIN(MAX(M29,0),F29) -> 722980190 | X29: =F29-W29 -> 2.4564028e+08 | Y29: =F29/SUMIFS($F$14:$F$35,$A$14:$A$35,A29) -> 0.053727973
A30: BANCO POPULAR | B30: 631309940-2 | C30: POP-631309940 | D30: Crédito | E30: CRED TESORERIA | F30: 287500000 | G30: 1 | H30: IBR 3 MESES | I30: 0.024 | J30: 0.14938678 | K30: 4 | L30: TRIMESTRAL | M30: 575000000 | N30: -287500000 | O30: 2 | P30: 46373 | Q30: 0.14938678 | R30: =IF(LEFT(H30,11)="IBR 6 MESES",Detalle_62!$B$7,IF(LEFT(H30,11)="IBR 3 MESES",Detalle_62!$B$6,IF(H30="DTF",Detalle_62!$B$8,Detalle_62!$B$5))) -> 0.11768 | S30: =(1+(R30+I30)/K30)^K30-1 -> 0.14938678 | T30: =(J30-S30)*10000 -> 0 | U30: =M30+N30-F30 -> 0 | V30: =IF(ABS(U30)>Resumen!$C$6,"ERROR",IF(OR(M30<0,N30<0),"ERROR","OK")) -> ERROR | W30: =MIN(MAX(M30,0),F30) -> 287500000 | X30: =F30-W30 -> 0 | Y30: =F30/SUMIFS($F$14:$F$35,$A$14:$A$35,A30) -> 1
A31: BBVA | B31: 252059 | C31: BBVA-0141 | D31: Crédito | E31: CRED TESORERIA | F31: 4700000000 | G31: 1 | H31: IBR 6 MESES/tri INT | I31: 0.01 | J31: 0.13542329 | K31: 2 | L31: SEMESTRAL | M31: 4700000000 | N31: 0 | O31: 1 | P31: 46367 | Q31: 0.13542329 | R31: =IF(LEFT(H31,11)="IBR 6 MESES",Detalle_62!$B$7,IF(LEFT(H31,11)="IBR 3 MESES",Detalle_62!$B$6,IF(H31="DTF",Detalle_62!$B$8,Detalle_62!$B$5))) -> 0.12025 | S31: =(1+(R31+I31)/K31)^K31-1 -> 0.13449127 | T31: =(J31-S31)*10000 -> 9.3202249 | U31: =M31+N31-F31 -> 0 | V31: =IF(ABS(U31)>Resumen!$C$6,"ERROR",IF(OR(M31<0,N31<0),"ERROR","OK")) -> OK | W31: =MIN(MAX(M31,0),F31) -> 4700000000 | X31: =F31-W31 -> 0 | Y31: =F31/SUMIFS($F$14:$F$35,$A$14:$A$35,A31) -> 1
A32: BANCOLOMBIA S.A. | B32: 1260105867 | C32: BCL-1260105867 | D32: Crédito | E32: CAPITAL DE TRABAJO | F32: 3.3333333e+09 | G32: 0.65303727 | H32: IBR 3 MESES | I32: 0.015 | J32: 0.14105339 | K32: 4 | L32: TRIMESTRAL | M32: 1.6666667e+09 | N32: 1.6666667e+09 | O32: 7 | P32: 46864 | Q32: 0.092113122 | R32: =IF(LEFT(H32,11)="IBR 6 MESES",Detalle_62!$B$7,IF(LEFT(H32,11)="IBR 3 MESES",Detalle_62!$B$6,IF(H32="DTF",Detalle_62!$B$8,Detalle_62!$B$5))) -> 0.11768 | S32: =(1+(R32+I32)/K32)^K32-1 -> 0.13942868 | T32: =(J32-S32)*10000 -> 16.247061 | U32: =M32+N32-F32 -> 0 | V32: =IF(ABS(U32)>Resumen!$C$6,"ERROR",IF(OR(M32<0,N32<0),"ERROR","OK")) -> OK | W32: =MIN(MAX(M32,0),F32) -> 1.6666667e+09 | X32: =F32-W32 -> 1.6666667e+09 | Y32: =F32/SUMIFS($F$14:$F$35,$A$14:$A$35,A32) -> 0.65303727
A33: BANCOLOMBIA S.A. | B33: LEASING 362095 | C33: BCL-L362095 | D33: Leasing | E33: EXCAVADORA PC130-8 KOMATSU | F33: 497241599 | G33: 0.097415189 | H33: IBR 3 MESES | I33: 0.0285 | J33: 0.15638274 | K33: 4 | L33: TRIMESTRAL | M33: 154259653 | N33: 342981946 | O33: 15 | P33: 47528 | Q33: 0.015234054 | R33: =IF(LEFT(H33,11)="IBR 6 MESES",Detalle_62!$B$7,IF(LEFT(H33,11)="IBR 3 MESES",Detalle_62!$B$6,IF(H33="DTF",Detalle_62!$B$8,Detalle_62!$B$5))) -> 0.11768 | S33: =(1+(R33+I33)/K33)^K33-1 -> 0.15439023 | T33: =(J33-S33)*10000 -> 19.925075 | U33: =M33+N33-F33 -> 0 | V33: =IF(ABS(U33)>Resumen!$C$6,"ERROR",IF(OR(M33<0,N33<0),"ERROR","OK")) -> OK | W33: =MIN(MAX(M33,0),F33) -> 154259653 | X33: =F33-W33 -> 342981946 | Y33: =F33/SUMIFS($F$14:$F$35,$A$14:$A$35,A33) -> 0.097415189
A34: BANCOLOMBIA S.A. | B34: LEASING 336817 | C34: BCL-L336817 | D34: Leasing | E34: TURBINA - TURBOKRAFT | F34: 7.7008543e+08 | G34: 0.15086835 | H34: IBR | I34: 0.032 | J34: 0.15794889 | K34: 12 | L34: MENSUAL | M34: 206513651 | N34: 5.6357177e+08 | O34: 58 | P34: 47995 | Q34: 0.023829488 | R34: =IF(LEFT(H34,11)="IBR 6 MESES",Detalle_62!$B$7,IF(LEFT(H34,11)="IBR 3 MESES",Detalle_62!$B$6,IF(H34="DTF",Detalle_62!$B$8,Detalle_62!$B$5))) -> 0.11555 | S34: =(1+(R34+I34)/K34)^K34-1 -> 0.15794889 | T34: =(J34-S34)*10000 -> 8.8817842e-12 | U34: =M34+N34-F34 -> 0 | V34: =IF(ABS(U34)>Resumen!$C$6,"ERROR",IF(OR(M34<0,N34<0),"ERROR","OK")) -> OK | W34: =MIN(MAX(M34,0),F34) -> 206513651 | X34: =F34-W34 -> 5.6357177e+08 | Y34: =F34/SUMIFS($F$14:$F$35,$A$14:$A$35,A34) -> 0.15086835
A35: BANCOLOMBIA S.A. | B35: LEASING 331330 | C35: BCL-L331330 | D35: Leasing | E35: PLANTA ELECTRICA CATERPILLAR C32-910 | F35: 503693510 | G35: 0.098679191 | H35: IBR | I35: 0.0375 | J35: 0.16425594 | K35: 12 | L35: MENSUAL | M35: 388559429 | N35: 115134081 | O35: 24 | P35: 46960 | Q35: 0.016208644 | R35: =IF(LEFT(H35,11)="IBR 6 MESES",Detalle_62!$B$7,IF(LEFT(H35,11)="IBR 3 MESES",Detalle_62!$B$6,IF(H35="DTF",Detalle_62!$B$8,Detalle_62!$B$5))) -> 0.11555 | S35: =(1+(R35+I35)/K35)^K35-1 -> 0.16425594 | T35: =(J35-S35)*10000 -> 0 | U35: =M35+N35-F35 -> 0 | V35: =IF(ABS(U35)>Resumen!$C$6,"ERROR",IF(OR(M35<0,N35<0),"ERROR","OK")) -> OK | W35: =MIN(MAX(M35,0),F35) -> 388559429 | X35: =F35-W35 -> 115134081 | Y35: =F35/SUMIFS($F$14:$F$35,$A$14:$A$35,A35) -> 0.098679191
E36: TOTAL OBLIGACIONES (recalculado) | F36: =SUM(F14:F35) -> 4.5185912e+10 | M36: =SUM(M14:M35) -> 2.1628999e+10 | N36: =SUM(N14:N35) -> 2.3809854e+10 | U36: =SUM(U14:U35) -> 2.5294057e+08 | W36: =SUM(W14:W35) -> 2.1341499e+10 | X36: =SUM(X14:X35) -> 2.3844413e+10
E37: Total obligaciones según cliente | F37: 4.5185912e+10
E38: Diferencia (recalculado − cliente) | F38: =F36-F37 -> 0
A40: Subtotales por banco – recálculo vs cliente
A41: Banco | F41: Subtotal recalculado | M41: Subtotal cliente | N41: Diferencia | Q41: Tasa pond. recalc. | R41: Tasa pond. cliente | S41: Dif. (pb)
A42: BANCO DAVIVIENDA | F42: =SUMIFS($F$14:$F$35,$A$14:$A$35,A42) -> 1.7065824e+10 | M42: 1.7065824e+10 | N42: =F42-M42 -> 0 | Q42: =SUMPRODUCT(($A$14:$A$35=A42)*$F$14:$F$35*$J$14:$J$35)/F42 -> 0.15728414 | R42: 0.15728414 | S42: =(R42-Q42)*10000 -> 0
A43: BANCO DE BOGOTA | F43: =SUMIFS($F$14:$F$35,$A$14:$A$35,A43) -> 1.8028234e+10 | M43: 1.8028234e+10 | N43: =F43-M43 -> 0 | Q43: =SUMPRODUCT(($A$14:$A$35=A43)*$F$14:$F$35*$J$14:$J$35)/F43 -> 0.14538155 | R43: 0.14538155 | S43: =(R43-Q43)*10000 -> 0
A44: BANCO POPULAR | F44: =SUMIFS($F$14:$F$35,$A$14:$A$35,A44) -> 287500000 | M44: 287500000 | N44: =F44-M44 -> 0 | Q44: =SUMPRODUCT(($A$14:$A$35=A44)*$F$14:$F$35*$J$14:$J$35)/F44 -> 0.14938678 | R44: 0.14938678 | S44: =(R44-Q44)*10000 -> 0
...

Sheet Certificados
A1: Cruce detalle 62 vs certificados / extractos bancarios (PDF adjunto)
A2: Fuente: ilovepdf_merged_1.pdf (25 págs.). Las págs. 3, 5, 7, 9, 11, 15, 23 y 25 son anexos/instructivos sin cifras. Capital banco 31-jul = capital certificado − abonos a capital entre corte y 31-jul.
A4: # | B4: Pág. PDF | C4: Banco | D4: Obligación (certificado) | E4: ID auditoría | F4: Tipo documento | G4: Fecha corte | H4: Capital s/certificado | I4: Abonos capital posteriores al corte (≤31-jul) | J4: Capital banco 31-jul-26 | K4: Saldo detalle 62 | L4: Diferencia detalle − banco | M4: Tasa EA certificado | N4: Tasa EA detalle | O4: Dif. (pb) | P4: Venc. certificado | Q4: Venc. detalle | R4: ¿Venc. coincide? | S4: Observaciones
A5: 1 | B5: 1 | C5: Davivienda | D5: 7000457300830624 | E5: DAV-830624 | F5: Extracto crédito corporativo | G5: 46102 | H5: =7499998630.82-127.57 -> 7.4999985e+09 | I5: 0 | J5: =IF(H5="","N/D",H5-I5) -> 7.4999985e+09 | K5: =SUMIFS(Detalle_62!$F$14:$F$35,Detalle_62!$C$14:$C$35,E5) -> 7500000000 | L5: =IF(H5="","N/D",K5-J5) -> 1496.75 | M5: 0.1551 | N5: =INDEX(Detalle_62!$J$14:$J$35,MATCH(E5,Detalle_62!$C$14:$C$35,0)) -> 0.15589377 | O5: =(N5-M5)*10000 -> 7.9376562 | P5: 52677 | Q5: =INDEX(Detalle_62!$P$14:$P$35,MATCH(E5,Detalle_62!$C$14:$C$35,0)) -> 52677 | R5: =IF(P5="","N/D",IF(P5=Q5,"Sí","NO")) -> Sí | S5: Saldo anterior 21-sep-25 $7.499.998.630,82 − abono capital 21-mar-26 $127,57. Próximo pago 21-sep-26 sólo intereses $565.738.188,80 (IBR semestral + 3,00).
A6: 2 | B6: 2 | C6: Banco de Bogotá | D6: 00856670629 | E6: BOG-856670629 | F6: Extracto Sustitución Finagro | G6: 46169 | H6: 1.6395e+09 | I6: 182166667 | J6: =IF(H6="","N/D",H6-I6) -> 1.4573333e+09 | K6: =SUMIFS(Detalle_62!$F$14:$F$35,Detalle_62!$C$14:$C$35,E6) -> 1457333332 | L6: =IF(H6="","N/D",K6-J6) -> 6.4100001 | M6: 0.1494 | N6: =INDEX(Detalle_62!$J$14:$J$35,MATCH(E6,Detalle_62!$C$14:$C$35,0)) -> 0.15829309 | O6: =(N6-M6)*10000 -> 88.930895 | Q6: =INDEX(Detalle_62!$P$14:$P$35,MATCH(E6,Detalle_62!$C$14:$C$35,0)) -> 46925 | R6: =IF(P6="","N/D",IF(P6=Q6,"Sí","NO")) -> N/D | S6: Cuota 12 (21-jun-26): capital $182.166.667 + intereses $59.390.887,23. Valor aprobado $2.186 MM, plazo 60 meses.
A7: 3 | B7: 4 | C7: Bancolombia | D7: 01260105867 | E7: BCL-1260105867 | F7: Detalle del crédito (Sucursal Virtual) | G7: 46245 | H7: 3333333334 | I7: 0 | J7: =IF(H7="","N/D",H7-I7) -> 3333333334 | K7: =SUMIFS(Detalle_62!$F$14:$F$35,Detalle_62!$C$14:$C$35,E7) -> 3.3333333e+09 | L7: =IF(H7="","N/D",K7-J7) -> -0.66666698 | M7: 0.1417 | N7: =INDEX(Detalle_62!$J$14:$J$35,MATCH(E7,Detalle_62!$C$14:$C$35,0)) -> 0.14105339 | O7: =(N7-M7)*10000 -> -6.4660895 | P7: 46865 | Q7: =INDEX(Detalle_62!$P$14:$P$35,MATCH(E7,Detalle_62!$C$14:$C$35,0)) -> 46864 | R7: =IF(P7="","N/D",IF(P7=Q7,"Sí","NO")) -> NO | S7: Capital vigente al 11-ago-26; sin abonos entre 31-jul y 11-ago. Intereses corrientes causados $24.607.407; próximo pago 22-oct-26. IBR + 1,5.
A8: 4 | B8: 6 | C8: Banco de Bogotá | D8: 00453436746 | E8: BOG-453436746 | F8: Extracto Ordinaria Comercial | G8: 46195 | H8: 3e+09 | I8: 62500000 | J8: =IF(H8="","N/D",H8-I8) -> 2.9375e+09 | K8: =SUMIFS(Detalle_62!$F$14:$F$35,Detalle_62!$C$14:$C$35,E8) -> 2937500000 | L8: =IF(H8="","N/D",K8-J8) -> 22.61 | M8: 0.1696 | N8: =INDEX(Detalle_62!$J$14:$J$35,MATCH(E8,Detalle_62!$C$14:$C$35,0)) -> 0.17522416 | O8: =(N8-M8)*10000 -> 56.241608 | Q8: =INDEX(Detalle_62!$P$14:$P$35,MATCH(E8,Detalle_62!$C$14:$C$35,0)) -> 47651 | R8: =IF(P8="","N/D",IF(P8=Q8,"Sí","NO")) -> N/D | S8: Cuota 100 (17-jul-26): capital $62.500.000 + intereses $38.894.999,71. Aprobado $7.500 MM, plazo 146 meses.
A9: 5 | B9: 8 | C9: Banco de Bogotá | D9: 00858177259 | E9: BOG-858177259 | F9: Extracto Sustitución Finagro | G9: 46234 | H9: 1.125e+09 | I9: 0 | J9: =IF(H9="","N/D",H9-I9) -> 1.125e+09 | K9: =SUMIFS(Detalle_62!$F$14:$F$35,Detalle_62!$C$14:$C$35,E9) -> 1125000000 | L9: =IF(H9="","N/D",K9-J9) -> 3.5899999 | M9: 0.1665 | N9: =INDEX(Detalle_62!$J$14:$J$35,MATCH(E9,Detalle_62!$C$14:$C$35,0)) -> 0.17400356 | O9: =(N9-M9)*10000 -> 75.035556 | Q9: =INDEX(Detalle_62!$P$14:$P$35,MATCH(E9,Detalle_62!$C$14:$C$35,0)) -> 46990 | R9: =IF(P9="","N/D",IF(P9=Q9,"Sí","NO")) -> N/D | S9: Corte 31-jul-26 (fecha de auditoría). Próxima cuota 25-ago-26: capital $125.000.000 + intereses $45.166.249,86.
A10: 6 | B10: 10 | C10: Banco de Bogotá | D10: 01155297469 → prorrogado 1159383796 | E10: BOG-1159383796 | F10: Extracto Sustitución Finagro | G10: 46190 | H10: 10000000000 | I10: 0 | J10: =IF(H10="","N/D",H10-I10) -> 10000000000 | K10: =SUMIFS(Detalle_62!$F$14:$F$35,Detalle_62!$C$14:$C$35,E10) -> 10000000000 | L10: =IF(H10="","N/D",K10-J10) -> 0 | M10: 0.1239 | N10: =INDEX(Detalle_62!$J$14:$J$35,MATCH(E10,Detalle_62!$C$14:$C$35,0)) -> 0.12962887 | O10: =(N10-M10)*10000 -> 57.288656 | Q10: =INDEX(Detalle_62!$P$14:$P$35,MATCH(E10,Detalle_62!$C$14:$C$35,0)) -> 46409 | R10: =IF(P10="","N/D",IF(P10=Q10,"Sí","NO")) -> N/D | S10: Cuota 2 (14-jul-26) por $10.299.617.737,55 incluye capital $10.000 MM. Contabilidad registra prórroga (NB-1016, 29-jul) al crédito 1159383796 – sin certificado del nuevo crédito.
A11: 7 | B11: 12 | C11: Davivienda | D11: 7000457300607691 | E11: DAV-607691 | F11: Extracto crédito corporativo | G11: 46050 | H11: 3.9599984e+09 | I11: =272300000-272299382.05 -> 617.95 | J11: =IF(H11="","N/D",H11-I11) -> 3.9599978e+09 | K11: =SUMIFS(Detalle_62!$F$14:$F$35,Detalle_62!$C$14:$C$35,E11) -> 3960000000 | L11: =IF(H11="","N/D",K11-J11) -> 2182.05 | M11: 0.1258 | N11: =INDEX(Detalle_62!$J$14:$J$35,MATCH(E11,Detalle_62!$C$14:$C$35,0)) -> 0.16019827 | O11: =(N11-M11)*10000 -> 343.98266 | P11: 51710 | Q11: =INDEX(Detalle_62!$P$14:$P$35,MATCH(E11,Detalle_62!$C$14:$C$35,0)) -> 51710 | R11: =IF(P11="","N/D",IF(P11=Q11,"Sí","NO")) -> Sí | S11: Pago 28-jul-26 de $272.300.000 vs intereses facturados $272.299.382,05: excedente $617,95 se aplica a capital.
A12: 8 | B12: 13 | C12: Davivienda | D12: 7000457300569032 | E12: DAV-569032 | F12: Extracto crédito corporativo | G12: 46050 | H12: 2.9999959e+09 | I12: =206288000-206287213.2 -> 786.8 | J12: =IF(H12="","N/D",H12-I12) -> 2999995157 | K12: =SUMIFS(Detalle_62!$F$14:$F$35,Detalle_62!$C$14:$C$35,E12) -> 3000000000 | L12: =IF(H12="","N/D",K12-J12) -> 4843 | M12: 0.1258 | N12: =INDEX(Detalle_62!$J$14:$J$35,MATCH(E12,Detalle_62!$C$14:$C$35,0)) -> 0.16019827 | O12: =(N12-M12)*10000 -> 343.98266 | P12: 51710 | Q12: =INDEX(Detalle_62!$P$14:$P$35,MATCH(E12,Detalle_62!$C$14:$C$35,0)) -> 51710 | R12: =IF(P12="","N/D",IF(P12=Q12,"Sí","NO")) -> Sí | S12: Pago 28-jul-26 de $206.288.000 vs intereses facturados $206.287.213,20: excedente $786,80 se aplica a capital.
A13: 9 | B13: 14 | C13: Davivienda Leasing | D13: 000030001021275-3 | E13: DAV-L1021275 | F13: Factura leasing | G13: 46209 | I13: 0 | J13: =IF(H13="","N/D",H13-I13) -> N/D | K13: =SUMIFS(Detalle_62!$F$14:$F$35,Detalle_62!$C$14:$C$35,E13) -> 1.8837122e+09 | L13: =IF(H13="","N/D",K13-J13) -> N/D | M13: 0.1441 | N13: =INDEX(Detalle_62!$J$14:$J$35,MATCH(E13,Detalle_62!$C$14:$C$35,0)) -> 0.14827711 | O13: =(N13-M13)*10000 -> 41.771146 | Q13: =INDEX(Detalle_62!$P$14:$P$35,MATCH(E13,Detalle_62!$C$14:$C$35,0)) -> 48235 | R13: =IF(P13="","N/D",IF(P13=Q13,"Sí","NO")) -> N/D | S13: Canon 006 (23-jul-26) sólo intereses $64.041.851; 16 cuotas pactadas. El extracto NO informa saldo de capital → ver saldo implícito en Recalculo_Intereses.
A14: 10 | B14: 16 | C14: Banco de Bogotá Leasing | D14: 00557285005 | E14: BOG-L557285005 | F14: Estado de cuenta leasing | G14: 46215 | H14: 1.047113e+09 | I14: 62866117 | J14: =IF(H14="","N/D",H14-I14) -> 9.8424689e+08 | K14: =SUMIFS(Detalle_62!$F$14:$F$35,Detalle_62!$C$14:$C$35,E14) -> 9.6862047e+08 | L14: =IF(H14="","N/D",K14-J14) -> -15626414 | M14: 0.1604 | N14: =INDEX(Detalle_62!$J$14:$J$35,MATCH(E14,Detalle_62!$C$14:$C$35,0)) -> 0.16478246 | O14: =(N14-M14)*10000 -> 43.824553 | P14: 47321 | Q14: =INDEX(Detalle_62!$P$14:$P$35,MATCH(E14,Detalle_62!$C$14:$C$35,0)) -> 47321 | R14: =IF(P14="","N/D",IF(P14=Q14,"Sí","NO")) -> Sí | S14: Saldo capital tras pago 22-abr-26; canon 22-jul-26 capital $62.866.117,12 / costo financiero $39.578.631,88. Opción de compra $16.220.758.
A15: 11 | B15: 17 | C15: Banco de Bogotá Leasing | D15: 00556449064 | E15: BOG-L556449064 | F15: Estado de cuenta leasing | G15: 46220 | H15: 2.8027464e+08 | I15: 26602534 | J15: =IF(H15="","N/D",H15-I15) -> 2.536721e+08 | K15: =SUMIFS(Detalle_62!$F$14:$F$35,Detalle_62!$C$14:$C$35,E15) -> 1.9672018e+08 | L15: =IF(H15="","N/D",K15-J15) -> -56951926 | M15: 0.1425 | N15: =INDEX(Detalle_62!$J$14:$J$35,MATCH(E15,Detalle_62!$C$14:$C$35,0)) -> 0.14541789 | O15: =(N15-M15)*10000 -> 29.178864 | P15: 46961 | Q15: =INDEX(Detalle_62!$P$14:$P$35,MATCH(E15,Detalle_62!$C$14:$C$35,0)) -> 46870 | R15: =IF(P15="","N/D",IF(P15=Q15,"Sí","NO")) -> NO | S15: Saldo tras pago 27-abr-26; canon 27-jul-26 capital $26.602.533,70 / costo financiero $9.497.274,30. DTF.
A16: 12 | B16: 18 | C16: Banco de Bogotá Leasing | D16: 00556449117 | E16: BOG-L556449117 | F16: Estado de cuenta leasing | G16: 46220 | H16: 2.8027464e+08 | I16: 26602534 | J16: =IF(H16="","N/D",H16-I16) -> 2.5367211e+08 | K16: =SUMIFS(Detalle_62!$F$14:$F$35,Detalle_62!$C$14:$C$35,E16) -> 1.9672018e+08 | L16: =IF(H16="","N/D",K16-J16) -> -56951927 | M16: 0.1425 | N16: =INDEX(Detalle_62!$J$14:$J$35,MATCH(E16,Detalle_62!$C$14:$C$35,0)) -> 0.14541789 | O16: =(N16-M16)*10000 -> 29.178864 | P16: 46961 | Q16: =INDEX(Detalle_62!$P$14:$P$35,MATCH(E16,Detalle_62!$C$14:$C$35,0)) -> 46870 | R16: =IF(P16="","N/D",IF(P16=Q16,"Sí","NO")) -> NO | S16: Saldo tras pago 27-abr-26; canon 27-jul-26 capital $26.602.533,71 / costo financiero $9.497.274,29. DTF.
A17: 13 | B17: 19 | C17: Banco de Bogotá Leasing | D17: 00556449180 | E17: BOG-L556449180 | F17: Estado de cuenta leasing | G17: 46216 | H17: 4.1765035e+08 | I17: 21538319 | J17: =IF(H17="","N/D",H17-I17) -> 3.9611203e+08 | K17: =SUMIFS(Detalle_62!$F$14:$F$35,Detalle_62!$C$14:$C$35,E17) -> 3.8184539e+08 | L17: =IF(H17="","N/D",K17-J17) -> -14266642 | M17: 0.1422 | N17: =INDEX(Detalle_62!$J$14:$J$35,MATCH(E17,Detalle_62!$C$14:$C$35,0)) -> 0.14541789 | O17: =(N17-M17)*10000 -> 32.178864 | P17: 47506 | Q17: =INDEX(Detalle_62!$P$14:$P$35,MATCH(E17,Detalle_62!$C$14:$C$35,0)) -> 47503 | R17: =IF(P17="","N/D",IF(P17=Q17,"Sí","NO")) -> NO | S17: Saldo tras pago 23-abr-26; canon 23-jul-26 capital $21.538.319,01 / costo financiero $14.118.857,99. DTF.
A18: 14 | B18: 20 | C18: Banco de Bogotá Leasing | D18: 00556449224 | E18: BOG-L556449224 | F18: Estado de cuenta leasing | G18: 46216 | H18: 4.1765035e+08 | I18: 21538319 | J18: =IF(H18="","N/D",H18-I18) -> 3.9611203e+08 | K18: =SUMIFS(Detalle_62!$F$14:$F$35,Detalle_62!$C$14:$C$35,E18) -> 3.8184539e+08 | L18: =IF(H18="","N/D",K18-J18) -> -14266642 | M18: 0.1422 | N18: =INDEX(Detalle_62!$J$14:$J$35,MATCH(E18,Detalle_62!$C$14:$C$35,0)) -> 0.14541789 | O18: =(N18-M18)*10000 -> 32.178864 | P18: 47506 | Q18: =INDEX(Detalle_62!$P$14:$P$35,MATCH(E18,Detalle_62!$C$14:$C$35,0)) -> 47503 | R18: =IF(P18="","N/D",IF(P18=Q18,"Sí","NO")) -> NO | S18: Saldo tras pago 23-abr-26; canon 23-jul-26 capital $21.538.319,02 / costo financiero $14.118.857,98. DTF.
A19: 15 | B19: 21 | C19: Banco de Bogotá Leasing | D19: 00556449288 | E19: BOG-L556449288 | F19: Estado de cuenta leasing | G19: 46213 | H19: 4.1773678e+08 | I19: 21542838 | J19: =IF(H19="","N/D",H19-I19) -> 3.9619394e+08 | K19: =SUMIFS(Detalle_62!$F$14:$F$35,Detalle_62!$C$14:$C$35,E19) -> 3.8264924e+08 | L19: =IF(H19="","N/D",K19-J19) -> -13544703 | M19: 0.1422 | N19: =INDEX(Detalle_62!$J$14:$J$35,MATCH(E19,Detalle_62!$C$14:$C$35,0)) -> 0.14541789 | O19: =(N19-M19)*10000 -> 32.178864 | P19: 47503 | Q19: =INDEX(Detalle_62!$P$14:$P$35,MATCH(E19,Detalle_62!$C$14:$C$35,0)) -> 47503 | R19: =IF(P19="","N/D",IF(P19=Q19,"Sí","NO")) -> Sí | S19: Saldo tras pago 20-abr-26; canon 20-jul-26 capital $21.542.838,16 / costo financiero $14.121.779,84. DTF.
A20: 16 | B20: 22 | C20: Davivienda Leasing | D20: 000030001019441-2 | E20: DAV-L1019441 | F20: Factura leasing | G20: 46198 | I20: 0 | J20: =IF(H20="","N/D",H20-I20) -> N/D | K20: =SUMIFS(Detalle_62!$F$14:$F$35,Detalle_62!$C$14:$C$35,E20) -> 3.9858217e+08 | L20: =IF(H20="","N/D",K20-J20) -> N/D | M20: 0.1603 | N20: =INDEX(Detalle_62!$J$14:$J$35,MATCH(E20,Detalle_62!$C$14:$C$35,0)) -> 0.16713318 | O20: =(N20-M20)*10000 -> 68.331817 | Q20: =INDEX(Detalle_62!$P$14:$P$35,MATCH(E20,Detalle_62!$C$14:$C$35,0)) -> 47037 | R20: =IF(P20="","N/D",IF(P20=Q20,"Sí","NO")) -> N/D | S20: Canon 033 (13-jul-26): capital $12.327.298, intereses $5.062.372, seguro $1.263.646. Último pago 11-jun-26 canon 032 $1.029.562 (sólo intereses). Sin saldo de capital.
A21: 17 | B21: 24 | C21: Davivienda Leasing | D21: 000030001019448-3 | E21: DAV-L1019448 | F21: Factura leasing | G21: 46191 | I21: 0 | J21: =IF(H21="","N/D",H21-I21) -> N/D | K21: =SUMIFS(Detalle_62!$F$14:$F$35,Detalle_62!$C$14:$C$35,E21) -> 3.2352969e+08 | L21: =IF(H21="","N/D",K21-J21) -> N/D | M21: 0.1593 | N21: =INDEX(Detalle_62!$J$14:$J$35,MATCH(E21,Detalle_62!$C$14:$C$35,0)) -> 0.16713318 | O21: =(N21-M21)*10000 -> 78.331817 | Q21: =INDEX(Detalle_62!$P$14:$P$35,MATCH(E21,Detalle_62!$C$14:$C$35,0)) -> 47098 | R21: =IF(P21="","N/D",IF(P21=Q21,"Sí","NO")) -> N/D | S21: Canon 031 (6-jul-26): capital $8.867.342, intereses $4.177.893. Último pago 5-jun-26 canon 030: capital $8.901.235, intereses $4.402.982. Sin saldo de capital.
F22: TOTAL obligaciones con saldo certificado | J22: =SUMIFS(J5:J21,$H$5:$H$21,"<>") -> 3.5993167e+10 | K22: =SUMIFS(K5:K21,$H$5:$H$21,"<>") -> 3.5821568e+10 | L22: =SUM(L5:L21) -> -1.715997e+08
F23: Diferencia detalle − banco: leasings Banco de Bogotá | L23: =SUMIFS(L5:L21,E5:E21,"BOG-L*") -> -1.7160825e+08
F24: Diferencia detalle − banco: créditos (redondeos) | L24: =L22-L23 -> 8553.7433
A26: B. Cobertura de confirmación – obligaciones del detalle 62 SIN certificado/extracto en el PDF
C27: Banco | D27: Obligación | E27: ID auditoría | F27: Tipo | K27: Saldo detalle 62
C28: BANCO POPULAR | D28: 631309940-2 | E28: POP-631309940 | F28: Crédito | K28: =SUMIFS(Detalle_62!$F$14:$F$35,Detalle_62!$C$14:$C$35,E28) -> 287500000
C29: BBVA | D29: 252059 | E29: BBVA-0141 | F29: Crédito | K29: =SUMIFS(Detalle_62!$F$14:$F$35,Detalle_62!$C$14:$C$35,E29) -> 4700000000
C30: BANCOLOMBIA S.A. | D30: LEASING 362095 | E30: BCL-L362095 | F30: Leasing | K30: =SUMIFS(Detalle_62!$F$14:$F$35,Detalle_62!$C$14:$C$35,E30) -> 497241599
C31: BANCOLOMBIA S.A. | D31: LEASING 336817 | E31: BCL-L336817 | F31: Leasing | K31: =SUMIFS(Detalle_62!$F$14:$F$35,Detalle_62!$C$14:$C$35,E31) -> 7.7008543e+08
C32: BANCOLOMBIA S.A. | D32: LEASING 331330 | E32: BCL-L331330 | F32: Leasing | K32: =SUMIFS(Detalle_62!$F$14:$F$35,Detalle_62!$C$14:$C$35,E32) -> 503693510
C33: Bancolombia | D33: Leasing 386735 (no está en detalle 62) | E33: BCL-L386735 | F33: Leasing | K33: =SUMIFS(Mayor_Mov!$F$5:$F$445,Mayor_Mov!$N$5:$N$445,E33)-SUMIFS(Mayor_Mov!$E$5:$E$445,Mayor_Mov!$N$5:$N$445,E33) -> 675837500
F34: Total sin certificado (detalle 62) | K34: =SUM(K28:K32) -> 6.7585205e+09
F35: % del saldo del detalle 62 cubierto con certificado/extracto | K35: =1-K34/Detalle_62!$F$36 -> 0.85042859
A37: C. Cruce de pagos/intereses según certificado vs registro contable (comprobantes del mayor)
C38: ID auditoría | D38: Concepto | E38: Documento contable | F38: Fecha | H38: Valor s/certificado | I38: Valor s/contabilidad | J38: Diferencia | S38: Comentario
C39: DAV-830624 | D39: Pago 21-mar-26 total aplicado (int. 445.207.872,43 + cap. 127,57) | E39: NI-00004268 | F39: =INDEX(Mayor_Mov!$H$5:$H$445,MATCH(E39,Mayor_Mov!$J$5:$J$445,0)) -> 46105 | H39: 445208000 | I39: =SUMIFS(Mayor_Mov!$E$5:$E$445,Mayor_Mov!$J$5:$J$445,E39,Mayor_Mov!$N$5:$N$445,C39) -> 445208000 | J39: =I39-H39 -> 0 | S39: El cliente reversa el total como interés; los $127,57 abonados a capital no se registran.
C40: DAV-607691 | D40: Pago 28-ene-26 total aplicado (int. 243.932.730,53 + cap. 269,47) | E40: NI-00004061 | F40: =INDEX(Mayor_Mov!$H$5:$H$445,MATCH(E40,Mayor_Mov!$J$5:$J$445,0)) -> 46051 | H40: 243933000 | I40: =SUMIFS(Mayor_Mov!$E$5:$E$445,Mayor_Mov!$J$5:$J$445,E40,Mayor_Mov!$N$5:$N$445,C40) -> 243933000 | J40: =I40-H40 -> 0 | S40: Capital $269,47 no registrado.
