Workbook

Sheet PT_62
C2: GUAICARAMO S.A.S.
C4: CLIENTE: | D4: GUAICARAMO S.A.S. | N4: PREPARADO: | O4: REVISADO: | P4: Ref. PT
C5: NIT: | D5: 860.040.584-0 | P5: 62 / 64
C6: PERIODO: | D6: 1-ene-2026 a 31-jul-2026 | N6: Fecha: | O6: Fecha:
C7: FECHA DE CORTE: | D7: =Resumen!C5 -> 46234 | N7: Iniciales y fecha del preparador / revisor
C8: NOMBRE P/T: | D8: OBLIGACIONES FINANCIERAS (cuenta 21 – papel 62/64)
C9: MARCO TÉCNICO: | D9: NIIF Plenas (Grupo 1): NIIF 9, NIIF 16, NIC 1, NIIF 7, NIC 23, NIC 24
C10: MONEDA: | D10: Pesos colombianos (COP)
C12: CÓMO LEER ESTE PAPEL (guía rápida)
C13: 1. Esta hoja resume TODO el trabajo: qué se revisó, cómo y qué se encontró. Las hojas de soporte están enlazadas al final (clic en el nombre).
C14: 2. Celdas BLANCAS = información del cliente, del balance o del banco. Celdas AMARILLAS = cálculos y recálculos hechos por auditoría.
C15: 3. 'OK' = la cifra cuadra. 'DIFERENCIA' = hay que revisar (la explicación está en la hoja 'Hallazgos'). [P] = falta un soporte (hoja 'Pendientes').
C16: 4. Orden sugerido de lectura: Conclusión (al final) → secciones 1 a 5 → hoja 'Pruebas_Auditoria' → hoja 'Tablas_Amortizacion' → 'Hallazgos'.
C18: OBJETIVO GENERAL
C19: Obtener evidencia suficiente y apropiada sobre la razonabilidad de los saldos de obligaciones financieras (créditos y pasivos por arrendamiento financiero) e intereses por pagar al 31-jul-2026, y del gasto financiero asociado, verificando integridad, existencia, exactitud, valuación a costo amortizado (método del interés efectivo – NIIF 9 §4.2.1 y B5.4; NIIF 16 §36), corte y clasificación corriente/no corriente (NIC 1 §69-76), con base en el balance de prueba, el auxiliar contable, el detalle 62, las tablas de amortización (papel 64) y los extractos/certificados bancarios.
C21: LIMITACIONES AL ALCANCE
C22: ="Se emite con "&Pendientes!$D$20&" pendientes de soporte (hoja Pendientes): certificados de saldo al 31-jul-26 de leasings Davivienda y Bancolombia, confirmaciones BBVA y Banco Popular, certificado del crédito Bogotá 1159383796, tablas del leasing 386735/GECOLSA y materialidad del encargo. Las conclusiones afectadas se marcan [P]." -> Se emite con 14 pendientes de soporte (hoja Pendientes): certificados de saldo al 31-jul-26 de leasings Davivienda y Bancolombia, confirmaciones BBVA y Banco Popular, certificado del crédito Bogotá 1159383796, tablas del leasing 386735/GECOLSA y materialidad del encargo. Las conclusiones afectadas se marcan [P].
C24: ASEVERACIONES
C25: Aseveración | D25: Procedimiento principal | E25: Hoja soporte | I25: Resultado
C26: Existencia / Ocurrencia | D26: Cotejo con certificados y extractos bancarios; pagos certificados vs comprobantes. | E26: Pruebas_Auditoria (bloque 2) | I26: ="Cobertura con extracto 2026: "&TEXT(Pruebas_Auditoria!$K$87,"0%")&"; diferencias de pagos: "&TEXT(Pruebas_Auditoria!J131,"#,##0") -> Cobertura con extracto 2026: 85%; diferencias de pagos: 11,975,072
C27: Integridad | D27: Movimiento vs balance; detalle 62 vs mayor por obligación; obligaciones del mayor no incluidas en el detalle. | E27: Pruebas_Auditoria (bloque 3) | I27: ="Mayor vs balance: "&Resumen!F11&". Leasing mayor − detalle 62: "&TEXT(Cruce_Detalle_Mayor!F7,"#,##0")&" (386735 y GECOLSA no están en el detalle)." -> Mayor vs balance: OK. Leasing mayor − detalle 62: 1,018,266,177 (386735 y GECOLSA no están en el detalle).
C28: Exactitud / Valuación | D28: Recálculo de intereses, de las tablas de amortización y de la causación al corte (NIIF 9 B5.4, NIIF 16 §36). | E28: Pruebas_Auditoria (bloque 4) / Tablas_Amortizacion (resumen) | I28: ="Causación no registrada al 31-jul: "&TEXT(Pruebas_Auditoria!K236,"#,##0")&"; tablas con error: 362095, Hoja2 (1159383796), costo amortizado Davivienda." -> Causación no registrada al 31-jul: 187,705,390; tablas con error: 362095, Hoja2 (1159383796), costo amortizado Davivienda.
C29: Corte | D29: Causación de intereses entre el último pago y el 31-jul; prórrogas y desembolsos cercanos al cierre. | E29: Pruebas_Auditoria (bloque 4) | I29: ="AJE-1 por "&TEXT(Pruebas_Auditoria!K236,"#,##0") -> AJE-1 por 187,705,390
C30: Derechos y obligaciones | D30: Titularidad de las obligaciones (NIT Guaicaramo) y obligaciones de terceros incluidas en el archivo de tablas. | E30: Tablas_Amortizacion (resumen) | I30: ="Crédito DYPSIS $72.300 MM en el archivo de tablas no está en el mayor: confirmar titular/garantías [P]." -> Crédito DYPSIS $72.300 MM en el archivo de tablas no está en el mayor: confirmar titular/garantías [P].
C31: Clasificación y presentación | D31: Porción corriente según tablas y vencimientos (NIC 1 §69); agrupación de tarjetas de crédito. | E31: Clasif_CP_LP | I31: ="Reclasificación LP→CP propuesta: "&TEXT(Clasif_CP_LP!B11+Clasif_CP_LP!B12,"#,##0") -> Reclasificación LP→CP propuesta: 1,576,635,656
C32: Revelación | D32: Datos para NIIF 7 (vencimientos, tasas variables IBR/DTF) y NIIF 16 (pasivos por arrendamiento). | E32: Detalle_62 / Tablas_Amortizacion (resumen) | I32: ="Tasas y vencimientos del detalle 62 difieren de los certificados en varias obligaciones (hallazgos 7 y 14)." -> Tasas y vencimientos del detalle 62 difieren de los certificados en varias obligaciones (hallazgos 7 y 14).
C34: TÉCNICAS DE AUDITORÍA APLICADAS
C35: ☑ Análisis ☑ Recálculo ☑ Inspección documental (extractos/certificados) ☑ Comparación (mayor ↔ detalle ↔ tabla ↔ banco) ☑ Prueba analítica sustantiva ☐ Confirmación externa (pendiente)
C37: PROCEDIMIENTOS
B38: # | C38: Procedimiento | I38: Ref. hoja | L38: Resultado
B39: 1 | C39: Cruzar el auxiliar de la cuenta 21 contra el balance de prueba (débitos, créditos y saldos) y comparar las dos versiones del balance. | I39: Pruebas_Auditoria (bloque 1) | L39: =Resumen!F11 -> OK
B40: 2 | C40: Reconstruir el saldo del mayor por obligación (detalle 31-dic-25 + movimientos 2026) y cruzarlo con el detalle 62. | I40: Pruebas_Auditoria (bloque 3) | L40: =IF(ABS(Pruebas_Auditoria!H177)+ABS(Pruebas_Auditoria!H181)<=Resumen!$C$6,"Por obligación cuadra con balance","Revisar") -> Por obligación cuadra con balance
B41: 3 | C41: Cotejar saldos, tasas, vencimientos y pagos con extractos/certificados bancarios. | I41: Pruebas_Auditoria (bloque 2) | L41: =Resumen!F16 -> DIFERENCIA
B42: 4 | C42: Revisar y recalcular las tablas de amortización del cliente (papel 64): aritmética, TIR, saldo al corte, porción corriente. | I42: Tablas_Amortizacion | L42: ="Tablas con hallazgos: 362095, Hoja2 (1159383796), costo amortizado Davivienda; "&COUNTIF(Tablas_Amortizacion!R12:R36,"N/D")&" sin saldo banco" -> Tablas con hallazgos: 362095, Hoja2 (1159383796), costo amortizado Davivienda; 4 sin saldo banco
B43: 5 | C43: Recalcular intereses liquidados por los bancos y la causación al 31-jul (costo amortizado). | I43: Pruebas_Auditoria (bloque 4) / Intereses_x_Obligacion | L43: =Resumen!F18 -> DIFERENCIA
B44: 6 | C44: Cruzar las cuentas de gasto financiero (5305) y de intereses por pagar (2130) contra la suma por obligación. | I44: Intereses_x_Obligacion | L44: =IF(ABS(Intereses_x_Obligacion!E38)<=Resumen!$C$6,"2130 cuadra por obligación","Revisar") -> 2130 cuadra por obligación
B45: 7 | C45: Prueba analítica sustantiva del gasto por intereses. | I45: Gasto_Intereses | L45: =Gasto_Intereses!B20 -> Gasto razonable dentro del umbral
B46: 8 | C46: Evaluar la clasificación corriente / no corriente y la presentación. | I46: Clasif_CP_LP | L46: ="Ver reclasificación AJE-2" -> Ver reclasificación AJE-2
B47: 9 | C47: Concluir y documentar hallazgos, ajustes y pendientes. | I47: Hallazgos / Pendientes | L47: =Pendientes!$D$20&" pendientes abiertos" -> 14 pendientes abiertos
C49: FUENTES DE INFORMACIÓN
...

Sheet Resumen
A1: GUAICARAMO S.A.S. – Auditoría de Obligaciones Financieras (cuenta 21 / papel 62) – corte 31-jul-2026
A2: Cruce movimiento ↔ detalle 62 ↔ certificados bancarios ↔ balance de prueba; recálculo de intereses (NIIF 9 costo amortizado, NIIF 16, NIC 1). Cifras en pesos colombianos. Azul = dato de la fuente; negro = fórmula; verde = vínculo a otra hoja; amarillo = cifra clave.
B4: Parámetros | E4: Estado del papel
B5: Fecha de corte | C5: 46234 | E5: ="Emitido con " & Pendientes!$D$20 & " pendientes" -> Emitido con 14 pendientes
B6: Umbral de diferencia trivial / redondeo (COP) | C6: 1000 | E6: Ver hoja 'Pendientes'
B7: Tolerancia recálculo de intereses (%) | C7: 0.02
B9: Resultados por prueba
B10: Prueba | C10: Valor A | D10: Valor B | E10: Diferencia | F10: Estado
B11: 1. Integridad: movimiento auxiliar vs balance – SF cuenta 21 | C11: =Pruebas_Auditoria!F21 -> -4.6662703e+10 | D11: =Pruebas_Auditoria!G21 -> -4.6662703e+10 | E11: =C11-D11 -> 0 | F11: =IF(ABS(E11)<=$C$6,"OK","DIFERENCIA") -> OK
B12: 2. Integridad: balance 29-sep vs balance 24-ago – nº cuentas con diferencias | C12: =Balance_21!$C$40 -> 0 | D12: =0 -> 0 | E12: =C12-D12 -> 0 | F12: =IF(ABS(E12)<=$C$6,"OK","DIFERENCIA") -> OK
B13: 3. Detalle 62: suma recalculada vs 'Total obligaciones' del cliente | C13: =Detalle_62!F36 -> 4.5185912e+10 | D13: =Detalle_62!F37 -> 4.5185912e+10 | E13: =C13-D13 -> 0 | F13: =IF(ABS(E13)<=$C$6,"OK","DIFERENCIA") -> OK
B14: 4. Créditos: detalle 62 vs mayor (21050100 + 21050201) | C14: =Cruce_Detalle_Mayor!D6 -> 3.8300667e+10 | D14: =Cruce_Detalle_Mayor!E6 -> 38300666666 | E14: =C14-D14 -> -0.66666412 | F14: =IF(ABS(E14)<=$C$6,"OK","DIFERENCIA") -> OK
B15: 5. Leasing: detalle 62 vs mayor (21202040 + 21202140) | C15: =Cruce_Detalle_Mayor!D7 -> 6.8852455e+09 | D15: =Cruce_Detalle_Mayor!E7 -> 7.9035116e+09 | E15: =C15-D15 -> -1.0182662e+09 | F15: =IF(ABS(E15)<=$C$6,"OK","DIFERENCIA") -> DIFERENCIA
B16: 6. Certificados: capital banco 31-jul vs detalle 62 (obligaciones con saldo certificado) | C16: =SUMIFS(Pruebas_Auditoria!J57:J73,Pruebas_Auditoria!H57:H73,"<>") -> 3.5993167e+10 | D16: =SUMIFS(Pruebas_Auditoria!K57:K73,Pruebas_Auditoria!H57:H73,"<>") -> 3.5821568e+10 | E16: =C16-D16 -> 1.715997e+08 | F16: =IF(ABS(E16)<=$C$6,"OK","DIFERENCIA") -> DIFERENCIA
B17: 7. Certificados: pagos/intereses certificados vs registrados (comprobantes) | C17: =Pruebas_Auditoria!H131 -> 3.3299172e+09 | D17: =Pruebas_Auditoria!I131 -> 3.3418922e+09 | E17: =C17-D17 -> -11975072 | F17: =IF(ABS(E17)<=$C$6,"OK","DIFERENCIA") -> DIFERENCIA
B18: 8. Recálculo de intereses liquidados por el banco (Parte 1) | C18: =Pruebas_Auditoria!J209+Pruebas_Auditoria!K209 -> 1.561142e+09 | D18: =Pruebas_Auditoria!J209 -> 1.6129345e+09 | E18: =C18-D18 -> -51792495 | F18: =IF(ABS(E18)<=$C$6,"OK","DIFERENCIA") -> DIFERENCIA
B19: 9. Intereses causados al 31-jul: recalculado vs registrado en 2130 | C19: =Pruebas_Auditoria!I236 -> 6.1509441e+08 | D19: =Pruebas_Auditoria!J236 -> 427389017 | E19: =C19-D19 -> 1.8770539e+08 | F19: =IF(ABS(E19)<=$C$6,"OK","DIFERENCIA") -> DIFERENCIA
B20: 10. Intereses por pagar: suma por obligación vs balance 2130 | C20: =Pruebas_Auditoria!J236 -> 427389017 | D20: =-Balance_21!$F$25 -> 4.2738902e+08 | E20: =C20-D20 -> -0.16000003 | F20: =IF(ABS(E20)<=$C$6,"OK","DIFERENCIA") -> OK
B22: Indicadores clave
B23: Saldo de capital según mayor 31-jul (2105 sin TC + 2120) | C23: =Gasto_Intereses!B5 -> 4.6204178e+10
B24: Saldo según detalle 62 | C24: =Detalle_62!F36 -> 4.5185912e+10
B25: Leasing 386735 omitido en el detalle 62 | C25: =Cruce_Detalle_Mayor!F14 -> 675837500
B26: Leasing GECOLSA (Davivienda) omitido en el detalle 62 | C26: =Cruce_Detalle_Mayor!F15 -> 213861900
B27: Leasings Bogotá: detalle 62 por debajo del mayor/certificados | C27: =Cruce_Detalle_Mayor!F16 -> 1.7160826e+08
B28: Diferencia de leasing sin explicar (residual) | C28: =Cruce_Detalle_Mayor!F19 -> 0
B29: % del saldo del detalle 62 cubierto con certificados | C29: =Pruebas_Auditoria!$K$87 -> 0.85042859
B30: Intereses no causados al 31-jul (AJE-1) | C30: =Pruebas_Auditoria!K236 -> 1.8770539e+08
B31: Reclasificación LP → CP propuesta (créditos + leasing) | C31: =Clasif_CP_LP!B11+Clasif_CP_LP!B12 -> 1.5766357e+09
B32: Gasto de intereses: desviación vs expectativa | C32: =Gasto_Intereses!$B$18 -> -0.071262153
B33: Conclusión prueba analítica | C33: =Gasto_Intereses!$B$20 -> Gasto razonable dentro del umbral
B35: Conclusión
B36: INTEGRIDAD – Mayor vs balance: el movimiento auxiliar de la cuenta 21 cuadra exactamente (débitos, créditos y saldos) con los dos balances de prueba, que son idénticos entre sí. Sin excepción.
B37: INTEGRIDAD – Detalle 62 vs mayor: los créditos cuadran (diferencia de redondeo $0,67). El leasing NO cuadra ($1.018 MM): leasing Bancolombia 386735 y leasing GECOLSA omitidos y saldos de tablas teóricas en el detalle; la diferencia queda explicada por obligación (Pruebas_Auditoria (bloque 3)).
B38: EXACTITUD – Certificados: los créditos cuadran con los extractos salvo redondeos de abonos a capital (< $5.000). Los leasings de Banco de Bogotá están subvalorados en el detalle 62. Los pagos registrados coinciden con los extractos, salvo el canon 032 del leasing 1019441.
B39: RECÁLCULO – La liquidación bancaria es razonable en base 365 (Bogotá Finagro en base 360), excepto Davivienda 607691/569032, cuya tasa declarada no reconcilia. Hay intereses causados no registrados al 31-jul (AJE-1) por la política de causación del cliente.
B40: PRESENTACIÓN – Se requiere reclasificar la porción corriente (NIC 1.69) y corregir los errores CP/LP del detalle 62. Ver la hoja 'Hallazgos'.
B41: PENDIENTES – El papel se emite sin certificados de saldo de leasings Davivienda/Bancolombia, sin confirmaciones de BBVA, Banco Popular y del crédito Bogotá 1159383796, sin tablas de amortización y sin materialidad del encargo. Las conclusiones afectadas quedan 'Pendiente de soporte' (ver hoja 'Pendientes').
B43: Hojas del libro
B44: Mayor_Mov | C44: Movimiento auxiliar ene–jul con el ID de obligación asignado por auditoría
B45: Balance_21 | C45: Cuentas 21/5305 de ambos balances de prueba y su comparación
...

Sheet Pruebas_Auditoria
A1: PRUEBAS DE AUDITORÍA – OBLIGACIONES FINANCIERAS – corte 31-jul-2026
A2: Cómo leer esta hoja: celdas BLANCAS = datos tomados del cliente, del balance o del banco; celdas AMARILLAS = cálculo o recálculo hecho por auditoría.
A3: 'OK' = la cifra cuadra; 'DIFERENCIA' = revisar (explicación en la columna de comentarios o en la hoja Hallazgos). Cifras en pesos colombianos.
A4: Contenido: BLOQUE 1 Movimiento vs balance · BLOQUE 2 Certificados bancarios · BLOQUE 3 Saldo por obligación · BLOQUE 4 Recálculo de intereses
A6: BLOQUE 1 – ¿El auxiliar contable de la cuenta 21 cuadra con el balance?
A7: Qué se hizo: se sumaron todos los débitos y créditos del auxiliar (ene–jul 2026) y se compararon con el balance de prueba.
A8: Cómo se lee: saldo inicial + débitos − créditos = saldo final calculado (amarillo), que se compara con el saldo final del balance.
A9: ="Resultado: "&M21&" – diferencia total en saldos: "&TEXT(H21,"#,##0") -> Resultado: OK – diferencia total en saldos: 0
A10: Cruce movimiento auxiliar (cuenta 21) vs balance de prueba – Integridad
A11: SI balance + Débitos movimiento − Créditos movimiento = SF calculado; se compara con SF del balance. Signo: crédito negativo.
A13: Cuenta | B13: Descripción | C13: Saldo inicial balance | D13: Débitos movimiento | E13: Créditos movimiento | F13: SF calculado | G13: SF balance | H13: Diferencia SF | I13: Débitos balance | J13: Dif. débitos | K13: Créditos balance | L13: Dif. créditos | M13: Estado
A14: 21050100 | B14: =INDEX(Balance_21!$B$6:$B$36,MATCH(A14,Balance_21!$A$6:$A$36,0)) -> Obl.Financiera Corto Plazo | C14: =Balance_21!$C$16 -> -17938333333 | D14: =SUMIFS(Mayor_Mov!$E$5:$E$445,Mayor_Mov!$B$5:$B$445,A14) -> 24700000000 | E14: =SUMIFS(Mayor_Mov!$F$5:$F$445,Mayor_Mov!$B$5:$B$445,A14) -> 24700000000 | F14: =C14+D14-E14 -> -17938333333 | G14: =Balance_21!$F$16 -> -17938333333 | H14: =F14-G14 -> 0 | I14: =Balance_21!$D$16 -> 24700000000 | J14: =D14-I14 -> 0 | K14: =Balance_21!$E$16 -> 24700000000 | L14: =E14-K14 -> 0 | M14: =IF(MAX(ABS(H14),ABS(J14),ABS(L14))<=Resumen!$C$6,"OK","DIFERENCIA") -> OK
A15: 21050201 | B15: =INDEX(Balance_21!$B$6:$B$36,MATCH(A15,Balance_21!$A$6:$A$36,0)) -> Obg.Financiera Largo Plazo | C15: =Balance_21!$C$18 -> -23368333333 | D15: =SUMIFS(Mayor_Mov!$E$5:$E$445,Mayor_Mov!$B$5:$B$445,A15) -> 3006000000 | E15: =SUMIFS(Mayor_Mov!$F$5:$F$445,Mayor_Mov!$B$5:$B$445,A15) -> 0 | F15: =C15+D15-E15 -> -20362333333 | G15: =Balance_21!$F$18 -> -20362333333 | H15: =F15-G15 -> 0 | I15: =Balance_21!$D$18 -> 3006000000 | J15: =D15-I15 -> 0 | K15: =Balance_21!$E$18 -> 0 | L15: =E15-K15 -> 0 | M15: =IF(MAX(ABS(H15),ABS(J15),ABS(L15))<=Resumen!$C$6,"OK","DIFERENCIA") -> OK
A16: 21050301 | B16: =INDEX(Balance_21!$B$6:$B$36,MATCH(A16,Balance_21!$A$6:$A$36,0)) -> Tarjeta de Credito por Pagar | C16: =Balance_21!$C$19 -> -25364582 | D16: =SUMIFS(Mayor_Mov!$E$5:$E$445,Mayor_Mov!$B$5:$B$445,A16) -> 1.1793557e+08 | E16: =SUMIFS(Mayor_Mov!$F$5:$F$445,Mayor_Mov!$B$5:$B$445,A16) -> 1.2370672e+08 | F16: =C16+D16-E16 -> -31135732 | G16: =Balance_21!$F$19 -> -31135732 | H16: =F16-G16 -> 0 | I16: =Balance_21!$D$19 -> 1.1793557e+08 | J16: =D16-I16 -> 0 | K16: =Balance_21!$E$19 -> 1.2370672e+08 | L16: =E16-K16 -> 0 | M16: =IF(MAX(ABS(H16),ABS(J16),ABS(L16))<=Resumen!$C$6,"OK","DIFERENCIA") -> OK
A17: 21202040 | B17: =INDEX(Balance_21!$B$6:$B$36,MATCH(A17,Balance_21!$A$6:$A$36,0)) -> Leasing Corto Plazo | C17: =Balance_21!$C$22 -> -5.8588019e+08 | D17: =SUMIFS(Mayor_Mov!$E$5:$E$445,Mayor_Mov!$B$5:$B$445,A17) -> 35428634 | E17: =SUMIFS(Mayor_Mov!$F$5:$F$445,Mayor_Mov!$B$5:$B$445,A17) -> 607791830 | F17: =C17+D17-E17 -> -1.1582434e+09 | G17: =Balance_21!$F$22 -> -1.1582434e+09 | H17: =F17-G17 -> 0 | I17: =Balance_21!$D$22 -> 35428634 | J17: =D17-I17 -> 0 | K17: =Balance_21!$E$22 -> 607791830 | L17: =E17-K17 -> 0 | M17: =IF(MAX(ABS(H17),ABS(J17),ABS(L17))<=Resumen!$C$6,"OK","DIFERENCIA") -> OK
A18: 21202140 | B18: =INDEX(Balance_21!$B$6:$B$36,MATCH(A18,Balance_21!$A$6:$A$36,0)) -> Leasing Largo Plazo | C18: =Balance_21!$C$24 -> -7.5446146e+09 | D18: =SUMIFS(Mayor_Mov!$E$5:$E$445,Mayor_Mov!$B$5:$B$445,A18) -> 9.110819e+08 | E18: =SUMIFS(Mayor_Mov!$F$5:$F$445,Mayor_Mov!$B$5:$B$445,A18) -> 111735587 | F18: =C18+D18-E18 -> -6.7452682e+09 | G18: =Balance_21!$F$24 -> -6.7452682e+09 | H18: =F18-G18 -> 0 | I18: =Balance_21!$D$24 -> 9.110819e+08 | J18: =D18-I18 -> 0 | K18: =Balance_21!$E$24 -> 111735587 | L18: =E18-K18 -> 0 | M18: =IF(MAX(ABS(H18),ABS(J18),ABS(L18))<=Resumen!$C$6,"OK","DIFERENCIA") -> OK
A19: 21300101 | B19: =INDEX(Balance_21!$B$6:$B$36,MATCH(A19,Balance_21!$A$6:$A$36,0)) -> Intereses Financieros por Pagar O.F. | C19: =Balance_21!$C$27 -> -1107168370 | D19: =SUMIFS(Mayor_Mov!$E$5:$E$445,Mayor_Mov!$B$5:$B$445,A19) -> 3257045166 | E19: =SUMIFS(Mayor_Mov!$F$5:$F$445,Mayor_Mov!$B$5:$B$445,A19) -> 2573515476 | F19: =C19+D19-E19 -> -423638680 | G19: =Balance_21!$F$27 -> -423638680 | H19: =F19-G19 -> 0 | I19: =Balance_21!$D$27 -> 3257045166 | J19: =D19-I19 -> 0 | K19: =Balance_21!$E$27 -> 2573515476 | L19: =E19-K19 -> 0 | M19: =IF(MAX(ABS(H19),ABS(J19),ABS(L19))<=Resumen!$C$6,"OK","DIFERENCIA") -> OK
A20: 21300102 | B20: =INDEX(Balance_21!$B$6:$B$36,MATCH(A20,Balance_21!$A$6:$A$36,0)) -> Intereses Leasing por Pagar | C20: =Balance_21!$C$28 -> -93054514 | D20: =SUMIFS(Mayor_Mov!$E$5:$E$445,Mayor_Mov!$B$5:$B$445,A20) -> 4.9871275e+08 | E20: =SUMIFS(Mayor_Mov!$F$5:$F$445,Mayor_Mov!$B$5:$B$445,A20) -> 409408571 | F20: =C20+D20-E20 -> -3750337.2 | G20: =Balance_21!$F$28 -> -3750337.2 | H20: =F20-G20 -> -2.6077032e-08 | I20: =Balance_21!$D$28 -> 4.9871275e+08 | J20: =D20-I20 -> 0 | K20: =Balance_21!$E$28 -> 409408571 | L20: =E20-K20 -> 0 | M20: =IF(MAX(ABS(H20),ABS(J20),ABS(L20))<=Resumen!$C$6,"OK","DIFERENCIA") -> OK
B21: TOTAL CUENTA 21 | C21: =SUM(C14:C20) -> -5.0662749e+10 | D21: =SUM(D14:D20) -> 3.2526204e+10 | E21: =SUM(E14:E20) -> 2.8526158e+10 | F21: =SUM(F14:F20) -> -4.6662703e+10 | G21: =SUM(G14:G20) -> -4.6662703e+10 | H21: =SUM(H14:H20) -> -2.6077032e-08 | I21: =SUM(I14:I20) -> 3.2526204e+10 | J21: =SUM(J14:J20) -> 0 | ... L21: =SUM(L14:L20) -> 0 | M21: =IF(MAX(ABS(H21),ABS(J21),ABS(L21))<=Resumen!$C$6,"OK","DIFERENCIA") -> OK
B22: Total cuenta 21 según balance (mayor) | C22: =Balance_21!$C$13 -> -5.0662749e+10 | G22: =Balance_21!$F$13 -> -4.6662703e+10 | I22: =Balance_21!$D$13 -> 3.2526204e+10 | K22: =Balance_21!$E$13 -> 2.8526158e+10
B23: Diferencia suma de auxiliares vs cuenta 21 | C23: =C21-C22 -> 0 | G23: =G21-G22 -> 0 | I23: =I21-I22 -> 0 | K23: =K21-K22 -> 0
A25: B. Integridad del archivo de movimiento ('Gran total' del reporte vs suma de líneas)
B26: Concepto | C26: Gran total reporte | D26: Suma líneas | E26: Diferencia
B27: Débitos | C27: 3.2526204e+10 | D27: =Mayor_Mov!E446 -> 3.2526204e+10 | E27: =C27-D27 -> 0
B28: Créditos | C28: 2.8526158e+10 | D28: =Mayor_Mov!F446 -> 2.8526158e+10 | E28: =C28-D28 -> 0
B29: Neto | C29: 4.0000458e+09 | D29: =Mayor_Mov!G446 -> 4.0000458e+09 | E29: =C29-D29 -> 0
B30: Nº de líneas del movimiento | D30: =COUNTA(Mayor_Mov!$B$5:$B$445) -> 441
A32: C. Consistencia jerárquica del balance y relación pasivo–gasto
B33: Prueba | C33: Valor A | D33: Valor B | E33: Diferencia | G33: Comentario
B34: SF 21 = 2105 + 2120 + 2130 | C34: =Balance_21!$F$13 -> -4.6662703e+10 | D34: =Balance_21!$F$14+Balance_21!$F$20+Balance_21!$F$25 -> -4.6662703e+10 | E34: =C34-D34 -> 0
B35: SF 2105 = 210501 + 210502 | C35: =Balance_21!$F$14 -> -3.8331802e+10 | D35: =Balance_21!$F$15+Balance_21!$F$17 -> -3.8331802e+10 | E35: =C35-D35 -> 0
B36: SF 210502 = 21050201 + 21050301 (tarjeta de crédito agrupada en LP) | C36: =Balance_21!$F$17 -> -2.0393469e+10 | D36: =Balance_21!$F$18+Balance_21!$F$19 -> -2.0393469e+10 | E36: =C36-D36 -> 0 | G36: Tarjeta de crédito (pasivo corriente) agrupada dentro de 'Obligaciones financieras a largo plazo' – ver hallazgo de clasificación.
B37: SF 2120 = 21202040 + 21202140 | C37: =Balance_21!$F$20 -> -7.9035116e+09 | D37: =Balance_21!$F$22+Balance_21!$F$24 -> -7.9035116e+09 | E37: =C37-D37 -> 0
B38: SF 2130 = 21300101 + 21300102 | C38: =Balance_21!$F$25 -> -4.2738902e+08 | D38: =Balance_21!$F$27+Balance_21!$F$28 -> -4.2738902e+08 | E38: =C38-D38 -> 0
B39: Ecuación: Activo + Pasivo + Patrimonio + Resultado (4+5+6+7) = 0 | C39: =Balance_21!$F$6+Balance_21!$F$7+Balance_21!$F$8 -> 1.8399439e+10 | D39: =-(Balance_21!$F$9+Balance_21!$F$10+Balance_21!$F$11+Balance_21!$F$12) -> 1.8399439e+10 | E39: =C39-D39 -> 0 | G39: Resultado del periodo ene–jul incluido vía clases 4 a 7.
B40: Intereses OF por pagar (21300101) = gasto causado neto (53052030) | C40: =-Balance_21!$F$27 -> 423638680 | D40: =Balance_21!$F$35 -> 423638680 | E40: =C40-D40 -> 0 | G40: El cliente reversa la causación al pagar y lleva el pago a 53052020; el saldo de 53052030 debe igualar el pasivo.
B41: Intereses leasing por pagar (21300102) = gasto causado neto (53052040) | C41: =-Balance_21!$F$28 -> 3750337.2 | D41: =Balance_21!$F$36 -> 3750337.3 | E41: =C41-D41 -> -0.16
B42: SI 21300101 = créditos 53052020 (reclasificación apertura) | C42: =-Balance_21!$C$27 -> 1107168370 | D42: =Balance_21!$E$34 -> 1107168370 | E42: =C42-D42 -> 0 | G42: Asiento de apertura: Db 53052030 / Cr 53052020 por el saldo inicial causado.
B43: SI 21300102 = créditos 53052010 (reclasificación apertura) | C43: =-Balance_21!$C$28 -> 93054514 | D43: =Balance_21!$E$33 -> 93054514 | E43: =C43-D43 -> 0
A45: D. Comparación de versiones del balance
...

Sheet Tablas_Amortizacion
A1: REVISIÓN DE LAS TABLAS DE AMORTIZACIÓN DEL CLIENTE (papel 64) – 25 tablas
A2: Cómo leer esta hoja: primero el RESUMEN de las 25 tablas; debajo, cada tabla completa (usa los enlaces de la columna 'Anexo' del resumen).
A3: En cada tabla: columnas A–G BLANCAS = tabla tal como la entregó el cliente; columnas H–P AMARILLAS = recálculo de auditoría.
A4: Si 'Dif. saldo' = 0 la tabla está bien calculada. 'Tabla − banco' muestra cuánto se aleja la tabla de lo que realmente cobra el banco.
A6: RESUMEN DE LA REVISIÓN DE TABLAS
A7: Cada fila es una tabla. La última columna ('Observación de auditoría') explica en palabras lo encontrado.
A8: Revisión y recálculo de las tablas de amortización del cliente (papel 64) – corte 31-jul-2026
A9: Cada fila resume un anexo Tablas_Amortizacion. Saldo banco desde Pruebas_Auditoria (bloque 3); interés registrado desde Intereses_x_Obligacion.
A11: ID auditoría | B11: Hoja cliente | C11: Anexo | D11: Banco | E11: Contrato | F11: Tipo | G11: Valor inicial | H11: Fecha inicio | I11: Tasa pactada | J11: TIR tabla (periodo) | K11: TIR recalc. | L11: Dif. TIR (pb) | M11: Última cuota ≤ corte | N11: Saldo tabla 31-jul | O11: Saldo detalle 62 | P11: Tabla − detalle 62 | Q11: Saldo banco 31-jul | R11: Tabla − banco | S11: Interés tabla ene–jul 26 | T11: Interés registrado 2026 | U11: Registrado − tabla | V11: CP 12m según tabla | W11: CP detalle 62 | X11: CP tabla − detalle | Y11: Máx. dif. recálculo saldo | Z11: Costo amortizado cliente (col. W) 31-jul | AA11: C. amortizado − saldo tabla | AB11: Observación de auditoría
A12: DAV-L1019441 | B12: 9441 | C12: A01-9441 | D12: BANCO DAVIVIENDA | E12: _0001019441 | F12: Leasing | G12: =C52 -> 726630000 | H12: =C53 -> 45210 | I12: =C54 -> 60 MESES – IBR+4% | J12: =IF(ISNUMBER(C55),C55,"Por fila") -> 0.013357044 | K12: =IFERROR(C56,"N/A") -> 0.013357044 | L12: =IF(AND(ISNUMBER(J12),ISNUMBER(K12)),(K12-J12)*10000,"N/A") -> -2.6194324e-12 | M12: =I52 -> 46214 | N12: =I53 -> 3.9858217e+08 | O12: =IF(COUNTIF(Detalle_62!$C$14:$C$35,A12)>0,SUMIFS(Detalle_62!$F$14:$F$35,Detalle_62!$C$14:$C$35,A12),"No está") -> 3.9858217e+08 | P12: =IF(ISNUMBER(O12),N12-O12,"N/A") -> 0 | Q12: =IFERROR(INDEX(Pruebas_Auditoria!$L$144:$L$183,MATCH("DAV-L1019441",Pruebas_Auditoria!$A$144:$A$183,0)),"N/D") -> 399387154 | R12: =IF(ISNUMBER(Q12),N12-Q12,"N/D") -> -804986.79 | S12: =I55 -> 41709582 | T12: =IFERROR(INDEX(Intereses_x_Obligacion!$I:$I,MATCH("DAV-L1019441",Intereses_x_Obligacion!$A:$A,0)),"N/D") -> 31222019 | U12: =IF(ISNUMBER(T12),T12-S12,"N/D") -> -10487563 | V12: =MAX(I56,0) -> 1.5968177e+08 | W12: =IF(COUNTIF(Detalle_62!$C$14:$C$35,A12)>0,SUMIFS(Detalle_62!$M$14:$M$35,Detalle_62!$C$14:$C$35,A12),"No está") -> 194846536 | X12: =IF(ISNUMBER(W12),V12-W12,"N/A") -> -35164770 | Y12: =I57 -> 7.4505806e-09 | Z12: N/A | AA12: N/A | AB12: Tabla teórica a tasa fija (TIR mensual constante) y cuota fija $17.681.217; el banco liquida a tasa variable (canon 033: capital $12.327.298 / interés $5.062.372). El saldo del detalle 62 es el de esta tabla, no el del banco.
A13: DAV-L1019448 | B13: 9448 | C13: A02-9448 | D13: BANCO DAVIVIENDA | E13: _0001019448-3 | F13: Leasing | G13: =C128 -> 560790000 | H13: =C129 -> 45265 | I13: =C130 -> 60 MESES – IBR+4% | J13: =IF(ISNUMBER(C131),C131,"Por fila") -> 0.012666707 | K13: =IFERROR(C132,"N/A") -> 0.012666707 | L13: =IF(AND(ISNUMBER(J13),ISNUMBER(K13)),(K13-J13)*10000,"N/A") -> -1.244959e-09 | M13: =I128 -> 46208 | N13: =I129 -> 3.2352969e+08 | O13: =IF(COUNTIF(Detalle_62!$C$14:$C$35,A13)>0,SUMIFS(Detalle_62!$F$14:$F$35,Detalle_62!$C$14:$C$35,A13),"No está") -> 3.2352969e+08 | P13: =IF(ISNUMBER(O13),N13-O13,"N/A") -> 0 | Q13: =IFERROR(INDEX(Pruebas_Auditoria!$L$144:$L$183,MATCH("DAV-L1019448",Pruebas_Auditoria!$A$144:$A$183,0)),"N/D") -> 332999135 | R13: =IF(ISNUMBER(Q13),N13-Q13,"N/D") -> -9469446.5 | S13: =I131 -> 31864026 | T13: =IFERROR(INDEX(Intereses_x_Obligacion!$I:$I,MATCH("DAV-L1019448",Intereses_x_Obligacion!$A:$A,0)),"N/D") -> 25643813 | U13: =IF(ISNUMBER(T13),T13-S13,"N/D") -> -6220212.6 | V13: =MAX(I132,0) -> 1.1973915e+08 | W13: =IF(COUNTIF(Detalle_62!$C$14:$C$35,A13)>0,SUMIFS(Detalle_62!$M$14:$M$35,Detalle_62!$C$14:$C$35,A13),"No está") -> 1.4201465e+08 | X13: =IF(ISNUMBER(W13),V13-W13,"N/A") -> -22275501 | Y13: =I133 -> 9.4994903e-08 | Z13: N/A | AA13: N/A | AB13: Tabla teórica a tasa fija y cuota constante; el banco liquida a tasa variable (canon 031: capital $8.867.342 / interés $4.177.893). Detalle 62 = saldo de la tabla.
A14: DAV-L1021275 | B14: 2753 | C14: A03-2753 | D14: BANCO DAVIVIENDA | E14: 30001021275-3 | F14: Leasing | G14: =C204 -> 1876684264 | H14: =C205 -> 45679 | I14: =C206 -> 84 MESES – IBR TV + 2,3 | J14: =IF(ISNUMBER(C207),C207,"Por fila") -> 0.027362714 | K14: =IFERROR(C208,"N/A") -> 0.027362714 | L14: =IF(AND(ISNUMBER(J14),ISNUMBER(K14)),(K14-J14)*10000,"N/A") -> -5.4123372e-12 | M14: =I204 -> 46225 | N14: =I205 -> 1.8837122e+09 | O14: =IF(COUNTIF(Detalle_62!$C$14:$C$35,A14)>0,SUMIFS(Detalle_62!$F$14:$F$35,Detalle_62!$C$14:$C$35,A14),"No está") -> 1.8837122e+09 | P14: =IF(ISNUMBER(O14),N14-O14,"N/A") -> 0 | Q14: =IFERROR(INDEX(Pruebas_Auditoria!$L$144:$L$183,MATCH("DAV-L1021275",Pruebas_Auditoria!$A$144:$A$183,0)),"N/D") -> 1876684264 | R14: =IF(ISNUMBER(Q14),N14-Q14,"N/D") -> 7027954.1 | S14: =I207 -> 1.5442855e+08 | T14: =IFERROR(INDEX(Intereses_x_Obligacion!$I:$I,MATCH("DAV-L1021275",Intereses_x_Obligacion!$A:$A,0)),"N/D") -> 138538864 | U14: =IF(ISNUMBER(T14),T14-S14,"N/D") -> -15889687 | V14: =MAX(I208,0) -> 0 | W14: =IF(COUNTIF(Detalle_62!$C$14:$C$35,A14)>0,SUMIFS(Detalle_62!$M$14:$M$35,Detalle_62!$C$14:$C$35,A14),"No está") -> 0 | X14: =IF(ISNUMBER(W14),V14-W14,"N/A") -> 0 | Y14: =I209 -> 0 | Z14: N/A | AA14: N/A | AB14: La TIR de la tabla supera el canon de sólo intereses de los primeros 12 trimestres: la tabla capitaliza intereses y el saldo crece ($1.876,7 MM → $1.883,7 MM). El banco mantiene el capital en $1.876.684.264 y cobra 14,41% EA ($64,0 MM en jul-26 vs $51,5 MM en la tabla).
A15: DAV-830624 | B15: D-0624 | C15: A04-D-0624 | D15: BANCO DAVIVIENDA | E15: 457300830624 | F15: Crédito | G15: =C248 -> 7500000000 | H15: =C249 -> 45372 | I15: =C250 -> 240 meses – IBR 6MESES + 3 | J15: =IF(ISNUMBER(C251),C251,"Por fila") -> Por fila | K15: =IFERROR(C252,"N/A") -> N/A | L15: =IF(AND(ISNUMBER(J15),ISNUMBER(K15)),(K15-J15)*10000,"N/A") -> N/A | M15: =I248 -> 46224 | N15: =I249 -> 7500000000 | O15: =IF(COUNTIF(Detalle_62!$C$14:$C$35,A15)>0,SUMIFS(Detalle_62!$F$14:$F$35,Detalle_62!$C$14:$C$35,A15),"No está") -> 7500000000 | P15: =IF(ISNUMBER(O15),N15-O15,"N/A") -> 0 | Q15: =IFERROR(INDEX(Pruebas_Auditoria!$L$144:$L$183,MATCH("DAV-830624",Pruebas_Auditoria!$A$144:$A$183,0)),"N/D") -> 7.4999985e+09 | R15: =IF(ISNUMBER(Q15),N15-Q15,"N/D") -> 1496.75 | S15: =I251 -> 639243750 | T15: =IFERROR(INDEX(Intereses_x_Obligacion!$I:$I,MATCH("DAV-830624",Intereses_x_Obligacion!$A:$A,0)),"N/D") -> 586251750 | U15: =IF(ISNUMBER(T15),T15-S15,"N/D") -> -52992000 | V15: =MAX(I252,0) -> 0 | W15: =IF(COUNTIF(Detalle_62!$C$14:$C$35,A15)>0,SUMIFS(Detalle_62!$M$14:$M$35,Detalle_62!$C$14:$C$35,A15),"No está") -> 0 | X15: =IF(ISNUMBER(W15),V15-W15,"N/A") -> 0 | Y15: =I253 -> 3.5762787e-07 | Z15: 5259837500 | AA15: =IF(ISNUMBER(Z15),Z15-N15,"N/A") -> -2240162500 | AB15: Interés mensual simple con IBR 6M + 3 pts / 12; el banco liquida semestre vencido a 15,51% EA. La columna 'medición al costo' (costo amortizado) resta los intereses del saldo: error de fórmula (ver columna Z).
A16: DAV-607691 | B16: D-7691 | C16: A05-D-7691 | D16: BANCO DAVIVIENDA | E16: 457300607691 | F16: Crédito | G16: =C504 -> 3960000000 | H16: =C505 -> 44405 | I16: =C506 -> 240 meses – IBR 6MESES +3,4 | J16: =IF(ISNUMBER(C507),C507,"Por fila") -> Por fila | K16: =IFERROR(C508,"N/A") -> N/A | L16: =IF(AND(ISNUMBER(J16),ISNUMBER(K16)),(K16-J16)*10000,"N/A") -> N/A | M16: =I504 -> 46231 | N16: =I505 -> 3960000000 | O16: =IF(COUNTIF(Detalle_62!$C$14:$C$35,A16)>0,SUMIFS(Detalle_62!$F$14:$F$35,Detalle_62!$C$14:$C$35,A16),"No está") -> 3960000000 | P16: =IF(ISNUMBER(O16),N16-O16,"N/A") -> 0 | Q16: =IFERROR(INDEX(Pruebas_Auditoria!$L$144:$L$183,MATCH("DAV-607691",Pruebas_Auditoria!$A$144:$A$183,0)),"N/D") -> 3.9599978e+09 | R16: =IF(ISNUMBER(Q16),N16-Q16,"N/D") -> 2182.05 | S16: =I507 -> 346760700 | T16: =IFERROR(INDEX(Intereses_x_Obligacion!$I:$I,MATCH("DAV-607691",Intereses_x_Obligacion!$A:$A,0)),"N/D") -> 309646400 | U16: =IF(ISNUMBER(T16),T16-S16,"N/D") -> -37114300 | V16: =MAX(I508,0) -> 0 | W16: =IF(COUNTIF(Detalle_62!$C$14:$C$35,A16)>0,SUMIFS(Detalle_62!$M$14:$M$35,Detalle_62!$C$14:$C$35,A16),"No está") -> 0 | X16: =IF(ISNUMBER(W16),V16-W16,"N/A") -> 0 | Y16: =I509 -> 2.1457672e-06 | Z16: 4.234723e+09 | AA16: =IF(ISNUMBER(Z16),Z16-N16,"N/A") -> 2.7472299e+08 | AB16: Interés mensual simple con IBR 6M + 3 pts; el contrato es IBR + 3,40 y el banco factura semestral. Columna de costo amortizado con el mismo error de fórmula (ver columna Z).
A17: DAV-569032 | B17: D-9032 | C17: A06-D-9032 | D17: BANCO DAVIVIENDA | E17: 457300569032 | F17: Crédito | G17: =C760 -> 3000000000 | H17: =C761 -> 44405 | I17: =C762 -> 240 meses – IBR 6MESES +3,4 | J17: =IF(ISNUMBER(C763),C763,"Por fila") -> Por fila | K17: =IFERROR(C764,"N/A") -> N/A | L17: =IF(AND(ISNUMBER(J17),ISNUMBER(K17)),(K17-J17)*10000,"N/A") -> N/A | M17: =I760 -> 46231 | N17: =I761 -> 3000000000 | O17: =IF(COUNTIF(Detalle_62!$C$14:$C$35,A17)>0,SUMIFS(Detalle_62!$F$14:$F$35,Detalle_62!$C$14:$C$35,A17),"No está") -> 3000000000 | P17: =IF(ISNUMBER(O17),N17-O17,"N/A") -> 0 | Q17: =IFERROR(INDEX(Pruebas_Auditoria!$L$144:$L$183,MATCH("DAV-569032",Pruebas_Auditoria!$A$144:$A$183,0)),"N/D") -> 2999995157 | R17: =IF(ISNUMBER(Q17),N17-Q17,"N/D") -> 4843 | S17: =I763 -> 262697500 | T17: =IFERROR(INDEX(Intereses_x_Obligacion!$I:$I,MATCH("DAV-569032",Intereses_x_Obligacion!$A:$A,0)),"N/D") -> 234581000 | U17: =IF(ISNUMBER(T17),T17-S17,"N/D") -> -28116500 | V17: =MAX(I764,0) -> 0 | W17: =IF(COUNTIF(Detalle_62!$C$14:$C$35,A17)>0,SUMIFS(Detalle_62!$M$14:$M$35,Detalle_62!$C$14:$C$35,A17),"No está") -> 0 | X17: =IF(ISNUMBER(W17),V17-W17,"N/A") -> 0 | Y17: =I765 -> 9.2387199e-07 | Z17: 3.2081235e+09 | AA17: =IF(ISNUMBER(Z17),Z17-N17,"N/A") -> 2.0812348e+08 | AB17: Igual que 607691: puntos adicionales de la tabla (3%) distintos al contrato (3,40%); costo amortizado mal formulado.
A18: BOG-453436746 | B18: B-6746 | C18: A07-B-6746 | D18: BANCO BOGOTA | E18: 453436746 | F18: Crédito | G18: =C1016 -> 7500000000 | H18: =C1017 -> 43207 | I18: =C1018 -> 144 meses – IBR +4,70 | J18: =IF(ISNUMBER(C1019),C1019,"Por fila") -> Por fila | K18: =IFERROR(C1020,"N/A") -> N/A | L18: =IF(AND(ISNUMBER(J18),ISNUMBER(K18)),(K18-J18)*10000,"N/A") -> N/A | M18: =I1016 -> 46220 | N18: =I1017 -> 2937500000 | O18: =IF(COUNTIF(Detalle_62!$C$14:$C$35,A18)>0,SUMIFS(Detalle_62!$F$14:$F$35,Detalle_62!$C$14:$C$35,A18),"No está") -> 2937500000 | P18: =IF(ISNUMBER(O18),N18-O18,"N/A") -> 0 | Q18: =IFERROR(INDEX(Pruebas_Auditoria!$L$144:$L$183,MATCH("BOG-453436746",Pruebas_Auditoria!$A$144:$A$183,0)),"N/D") -> 2.9375e+09 | R18: =IF(ISNUMBER(Q18),N18-Q18,"N/D") -> 22.61 | S18: =I1019 -> 2.8421922e+08 | T18: =IFERROR(INDEX(Intereses_x_Obligacion!$I:$I,MATCH("BOG-453436746",Intereses_x_Obligacion!$A:$A,0)),"N/D") -> 2.3229766e+08 | U18: =IF(ISNUMBER(T18),T18-S18,"N/D") -> -51921555 | V18: =MAX(I1020,0) -> 750000000 | W18: =IF(COUNTIF(Detalle_62!$C$14:$C$35,A18)>0,SUMIFS(Detalle_62!$M$14:$M$35,Detalle_62!$C$14:$C$35,A18),"No está") -> 750000000 | X18: =IF(ISNUMBER(W18),V18-W18,"N/A") -> 0 | Y18: =I1021 -> 0 | Z18: 3.2226743e+09 | AA18: =IF(ISNUMBER(Z18),Z18-N18,"N/A") -> 2.8517427e+08 | AB18: Capital fijo $62,5 MM mensual coincide con el banco; el interés de la tabla usa el IBR proyectado.
A19: BOG-856670629 | B19: B-0629 | C19: A08-B-0629 | D19: BANCO DE BOGOTA | E19: 856670629 | F19: Crédito | G19: =C1178 -> 2186000000 | H19: =C1179 -> 45098 | I19: =C1180 -> 60 meses – IBR(3M) + 3,2% | J19: =IF(ISNUMBER(C1181),C1181,"Por fila") -> Por fila | K19: =IFERROR(C1182,"N/A") -> N/A | L19: =IF(AND(ISNUMBER(J19),ISNUMBER(K19)),(K19-J19)*10000,"N/A") -> N/A | M19: =I1178 -> 46224 | N19: =I1179 -> 1457333336 | O19: =IF(COUNTIF(Detalle_62!$C$14:$C$35,A19)>0,SUMIFS(Detalle_62!$F$14:$F$35,Detalle_62!$C$14:$C$35,A19),"No está") -> 1457333332 | P19: =IF(ISNUMBER(O19),N19-O19,"N/A") -> 4 | Q19: =IFERROR(INDEX(Pruebas_Auditoria!$L$144:$L$183,MATCH("BOG-856670629",Pruebas_Auditoria!$A$144:$A$183,0)),"N/D") -> 1.4573333e+09 | R19: =IF(ISNUMBER(Q19),N19-Q19,"N/D") -> 10.41 | S19: =I1181 -> 1.4013201e+08 | T19: =IFERROR(INDEX(Intereses_x_Obligacion!$I:$I,MATCH("BOG-856670629",Intereses_x_Obligacion!$A:$A,0)),"N/D") -> 133305619 | U19: =IF(ISNUMBER(T19),T19-S19,"N/D") -> -6826393.2 | V19: =MAX(I1182,0) -> 728666668 | W19: =IF(COUNTIF(Detalle_62!$C$14:$C$35,A19)>0,SUMIFS(Detalle_62!$M$14:$M$35,Detalle_62!$C$14:$C$35,A19),"No está") -> 750000000 | X19: =IF(ISNUMBER(W19),V19-W19,"N/A") -> -21333332 | Y19: =I1183 -> 0 | Z19: 1.4730309e+09 | AA19: =IF(ISNUMBER(Z19),Z19-N19,"N/A") -> 15697543 | AB19: Capital trimestral $182,2 MM coincide con el banco (diferencia de redondeo en el saldo).
A20: BOG-858177259 | B20: B-7259 | C20: A09-B-7259 | D20: BANCO DE BOGOTA | E20: 858177259 | F20: Crédito | G20: =C1254 -> 2500000000 | H20: =C1255 -> 45163 | I20: =C1256 -> 60 meses – IBR(3M) + 4,6% | J20: =IF(ISNUMBER(C1257),C1257,"Por fila") -> Por fila | K20: =IFERROR(C1258,"N/A") -> 0.012817645 | L20: =IF(AND(ISNUMBER(J20),ISNUMBER(K20)),(K20-J20)*10000,"N/A") -> N/A | M20: =I1254 -> 46224 | N20: =I1255 -> 1125000000 | O20: =IF(COUNTIF(Detalle_62!$C$14:$C$35,A20)>0,SUMIFS(Detalle_62!$F$14:$F$35,Detalle_62!$C$14:$C$35,A20),"No está") -> 1125000000 | P20: =IF(ISNUMBER(O20),N20-O20,"N/A") -> 0 | Q20: =IFERROR(INDEX(Pruebas_Auditoria!$L$144:$L$183,MATCH("BOG-858177259",Pruebas_Auditoria!$A$144:$A$183,0)),"N/D") -> 1.125e+09 | R20: =IF(ISNUMBER(Q20),N20-Q20,"N/D") -> 3.5899999 | S20: =I1257 -> 108575000 | T20: =IFERROR(INDEX(Intereses_x_Obligacion!$I:$I,MATCH("BOG-858177259",Intereses_x_Obligacion!$A:$A,0)),"N/D") -> 108941341 | U20: =IF(ISNUMBER(T20),T20-S20,"N/D") -> 366341 | V20: =MAX(I1258,0) -> 500000000 | W20: =IF(COUNTIF(Detalle_62!$C$14:$C$35,A20)>0,SUMIFS(Detalle_62!$M$14:$M$35,Detalle_62!$C$14:$C$35,A20),"No está") -> 500000000 | X20: =IF(ISNUMBER(W20),V20-W20,"N/A") -> 0 | Y20: =I1259 -> 0 | Z20: 1.1354471e+09 | AA20: =IF(ISNUMBER(Z20),Z20-N20,"N/A") -> 10447091 | AB20: Capital trimestral $125 MM coincide con el banco.
A21: BOG-1155297469 | B21: B-7469 | C21: A10-B-7469 | D21: BANCO DE BOGOTA | E21: 1155297469 | F21: Crédito | G21: =C1330 -> 10000000000 | H21: =C1331 -> 46036 | I21: =C1332 -> 6 meses – IBR(3M) + 0,8% | J21: =IF(ISNUMBER(C1333),C1333,"Por fila") -> Por fila | K21: =IFERROR(C1334,"N/A") -> 0.01006648 | L21: =IF(AND(ISNUMBER(J21),ISNUMBER(K21)),(K21-J21)*10000,"N/A") -> N/A | M21: =I1330 -> 46217 | N21: =I1331 -> 0 | O21: =IF(COUNTIF(Detalle_62!$C$14:$C$35,A21)>0,SUMIFS(Detalle_62!$F$14:$F$35,Detalle_62!$C$14:$C$35,A21),"No está") -> No está | P21: =IF(ISNUMBER(O21),N21-O21,"N/A") -> N/A | Q21: =IFERROR(INDEX(Pruebas_Auditoria!$L$144:$L$183,MATCH("BOG-1155297469",Pruebas_Auditoria!$A$144:$A$183,0)),"N/D") -> N/D | R21: =IF(ISNUMBER(Q21),N21-Q21,"N/D") -> N/D | S21: =I1333 -> 604300000 | T21: =IFERROR(INDEX(Intereses_x_Obligacion!$I:$I,MATCH("BOG-1155297469",Intereses_x_Obligacion!$A:$A,0)),"N/D") -> N/D | U21: =IF(ISNUMBER(T21),T21-S21,"N/D") -> N/D | V21: =MAX(I1334,0) -> 0 | W21: =IF(COUNTIF(Detalle_62!$C$14:$C$35,A21)>0,SUMIFS(Detalle_62!$M$14:$M$35,Detalle_62!$C$14:$C$35,A21),"No está") -> No está | X21: =IF(ISNUMBER(W21),V21-W21,"N/A") -> N/A | Y21: =I1335 -> 0 | Z21: 0 | AA21: =IF(ISNUMBER(Z21),Z21-N21,"N/A") -> 0 | AB21: Tabla del crédito cancelado/prorrogado el 14/29-jul-26.
A22: BOG-1159383796 | B22: Hoja2 | C22: A11-Hoja2 | D22: BANCO DE BOGOTA | E22: 1159383796 | F22: Crédito | G22: =C1352 -> 10000000000 | H22: =C1353 -> 46225 | I22: =C1354 -> 6 meses – IBR(3M) + 0,8% | J22: =IF(ISNUMBER(C1355),C1355,"Por fila") -> Por fila | K22: =IFERROR(C1356,"N/A") -> 0.01006648 | L22: =IF(AND(ISNUMBER(J22),ISNUMBER(K22)),(K22-J22)*10000,"N/A") -> N/A | M22: =I1352 -> 46225 | N22: =I1353 -> 10000000000 | O22: =IF(COUNTIF(Detalle_62!$C$14:$C$35,A22)>0,SUMIFS(Detalle_62!$F$14:$F$35,Detalle_62!$C$14:$C$35,A22),"No está") -> 10000000000 | P22: =IF(ISNUMBER(O22),N22-O22,"N/A") -> 0 | Q22: =IFERROR(INDEX(Pruebas_Auditoria!$L$144:$L$183,MATCH("BOG-1159383796",Pruebas_Auditoria!$A$144:$A$183,0)),"N/D") -> 10000000000 | R22: =IF(ISNUMBER(Q22),N22-Q22,"N/D") -> 0 | S22: =I1355 -> 604300000 | T22: =IFERROR(INDEX(Intereses_x_Obligacion!$I:$I,MATCH("BOG-1159383796",Intereses_x_Obligacion!$A:$A,0)),"N/D") -> 554228055 | U22: =IF(ISNUMBER(T22),T22-S22,"N/D") -> -50071945 | V22: =MAX(I1356,0) -> 0 | W22: =IF(COUNTIF(Detalle_62!$C$14:$C$35,A22)>0,SUMIFS(Detalle_62!$M$14:$M$35,Detalle_62!$C$14:$C$35,A22),"No está") -> 10000000000 | X22: =IF(ISNUMBER(W22),V22-W22,"N/A") -> -10000000000 | Y22: =I1357 -> 0 | Z22: 0 | AA22: =IF(ISNUMBER(Z22),Z22-N22,"N/A") -> -10000000000 | AB22: La hoja 'Hoja2' es copia de la tabla del 1155297469: fechas feb–jul 2026 anteriores al inicio (22-jul-26) y saldo cero al 14-jul. No sirve como tabla del crédito nuevo.
A23: BOG-L556449224 | B23: 9224 | C23: A12-9224 | D23: BANCO DE BOGOTA | E23: 556449224 | F23: Leasing | G23: =C1374 -> 569902000 | H23: =C1375 -> 44946 | I23: =C1376 -> 28 TRIMESTRES – DTF+3,57% | J23: =IF(ISNUMBER(C1377),C1377,"Por fila") -> 0.036189196 | K23: =IFERROR(C1378,"N/A") -> 0.036189196 | L23: =IF(AND(ISNUMBER(J23),ISNUMBER(K23)),(K23-J23)*10000,"N/A") -> -1.179612e-11 | M23: =I1374 -> 46223 | N23: =I1375 -> 3.8184539e+08 | O23: =IF(COUNTIF(Detalle_62!$C$14:$C$35,A23)>0,SUMIFS(Detalle_62!$F$14:$F$35,Detalle_62!$C$14:$C$35,A23),"No está") -> 3.8184539e+08 | P23: =IF(ISNUMBER(O23),N23-O23,"N/A") -> 0 | Q23: =IFERROR(INDEX(Pruebas_Auditoria!$L$144:$L$183,MATCH("BOG-L556449224",Pruebas_Auditoria!$A$144:$A$183,0)),"N/D") -> 3.9611203e+08 | R23: =IF(ISNUMBER(Q23),N23-Q23,"N/D") -> -14266642 | S23: =I1377 -> 45776937 | T23: =IFERROR(INDEX(Intereses_x_Obligacion!$I:$I,MATCH("BOG-L556449224",Intereses_x_Obligacion!$A:$A,0)),"N/D") -> 31068671 | U23: =IF(ISNUMBER(T23),T23-S23,"N/D") -> -14708266 | V23: =MAX(I1378,0) -> 89122277 | W23: =IF(COUNTIF(Detalle_62!$C$14:$C$35,A23)>0,SUMIFS(Detalle_62!$M$14:$M$35,Detalle_62!$C$14:$C$35,A23),"No está") -> 1.7563157e+08 | X23: =IF(ISNUMBER(W23),V23-W23,"N/A") -> -86509292 | Y23: =I1379 -> 4.4703484e-08 | Z23: N/A | AA23: N/A | AB23: Tabla a tasa fija; el banco liquida DTF variable: saldo certificado mayor que el de la tabla.
A24: BOG-L556449180 | B24: 9180 | C24: A13-9180 | D24: BANCO DE BOGOTA | E24: 556449180 | F24: Leasing | G24: =C1418 -> 569902000 | H24: =C1419 -> 44949 | I24: =C1420 -> 28 TRIMESTRES – DTF+3,57% | J24: =IF(ISNUMBER(C1421),C1421,"Por fila") -> 0.036189196 | K24: =IFERROR(C1422,"N/A") -> 0.036189196 | L24: =IF(AND(ISNUMBER(J24),ISNUMBER(K24)),(K24-J24)*10000,"N/A") -> -1.179612e-11 | M24: =I1418 -> 46226 | N24: =I1419 -> 3.8184539e+08 | O24: =IF(COUNTIF(Detalle_62!$C$14:$C$35,A24)>0,SUMIFS(Detalle_62!$F$14:$F$35,Detalle_62!$C$14:$C$35,A24),"No está") -> 3.8184539e+08 | P24: =IF(ISNUMBER(O24),N24-O24,"N/A") -> 0 | Q24: =IFERROR(INDEX(Pruebas_Auditoria!$L$144:$L$183,MATCH("BOG-L556449180",Pruebas_Auditoria!$A$144:$A$183,0)),"N/D") -> 3.9611203e+08 | R24: =IF(ISNUMBER(Q24),N24-Q24,"N/D") -> -14266642 | S24: =I1421 -> 45776937 | T24: =IFERROR(INDEX(Intereses_x_Obligacion!$I:$I,MATCH("BOG-L556449180",Intereses_x_Obligacion!$A:$A,0)),"N/D") -> 31068672 | U24: =IF(ISNUMBER(T24),T24-S24,"N/D") -> -14708265 | V24: =MAX(I1422,0) -> 89122277 | W24: =IF(COUNTIF(Detalle_62!$C$14:$C$35,A24)>0,SUMIFS(Detalle_62!$M$14:$M$35,Detalle_62!$C$14:$C$35,A24),"No está") -> 1.7563157e+08 | X24: =IF(ISNUMBER(W24),V24-W24,"N/A") -> -86509292 | Y24: =I1423 -> 4.4703484e-08 | Z24: N/A | AA24: N/A | AB24: Tabla a tasa fija; el banco liquida DTF variable: saldo certificado mayor que el de la tabla.
A25: BOG-L556449117 | B25: 9117 | C25: A14-9117 | D25: BANCO DE BOGOTA | E25: 556449117 | F25: Leasing | G25: =C1462 -> 569902000 | H25: =C1463 -> 44404 | I25: =C1464 -> 28 TRIMESTRES – DTF+3,57% | J25: =IF(ISNUMBER(C1465),C1465,"Por fila") -> 0.0059356385 | K25: =IFERROR(C1466,"N/A") -> 0.0059356385 | L25: =IF(AND(ISNUMBER(J25),ISNUMBER(K25)),(K25-J25)*10000,"N/A") -> 2.6801478e-12 | M25: =I1462 -> 46230 | N25: =I1463 -> 1.9672018e+08 | O25: =IF(COUNTIF(Detalle_62!$C$14:$C$35,A25)>0,SUMIFS(Detalle_62!$F$14:$F$35,Detalle_62!$C$14:$C$35,A25),"No está") -> 1.9672018e+08 | P25: =IF(ISNUMBER(O25),N25-O25,"N/A") -> 0 | Q25: =IFERROR(INDEX(Pruebas_Auditoria!$L$144:$L$183,MATCH("BOG-L556449117",Pruebas_Auditoria!$A$144:$A$183,0)),"N/D") -> 2.5367211e+08 | R25: =IF(ISNUMBER(Q25),N25-Q25,"N/D") -> -56951927 | S25: =I1465 -> 4327677.9 | T25: =IFERROR(INDEX(Intereses_x_Obligacion!$I:$I,MATCH("BOG-L556449117",Intereses_x_Obligacion!$A:$A,0)),"N/D") -> 28058555 | U25: =IF(ISNUMBER(T25),T25-S25,"N/D") -> 23730877 | V25: =MAX(I1466,0) -> 94380151 | W25: =IF(COUNTIF(Detalle_62!$C$14:$C$35,A25)>0,SUMIFS(Detalle_62!$M$14:$M$35,Detalle_62!$C$14:$C$35,A25),"No está") -> 1.7563157e+08 | X25: =IF(ISNUMBER(W25),V25-W25,"N/A") -> -81251418 | Y25: =I1467 -> 4.4703484e-08 | Z25: N/A | AA25: N/A | AB25: Tabla a tasa fija con TIR muy baja (0,59% trimestral) y capital acelerado: saldo $57 MM por debajo del banco.
A26: BOG-L556449064 | B26: 9064 | C26: A15-9064 | D26: BANCO DE BOGOTA | E26: 556449064 | F26: Leasing | G26: =C1506 -> 569902000 | H26: =C1507 -> 44404 | I26: =C1508 -> 28 TRIMESTRES – DTF+3,57% | J26: =IF(ISNUMBER(C1509),C1509,"Por fila") -> 0.0059356385 | K26: =IFERROR(C1510,"N/A") -> 0.0059356385 | L26: =IF(AND(ISNUMBER(J26),ISNUMBER(K26)),(K26-J26)*10000,"N/A") -> 2.6801478e-12 | M26: =I1506 -> 46230 | N26: =I1507 -> 1.9672018e+08 | O26: =IF(COUNTIF(Detalle_62!$C$14:$C$35,A26)>0,SUMIFS(Detalle_62!$F$14:$F$35,Detalle_62!$C$14:$C$35,A26),"No está") -> 1.9672018e+08 | P26: =IF(ISNUMBER(O26),N26-O26,"N/A") -> 0 | Q26: =IFERROR(INDEX(Pruebas_Auditoria!$L$144:$L$183,MATCH("BOG-L556449064",Pruebas_Auditoria!$A$144:$A$183,0)),"N/D") -> 2.536721e+08 | R26: =IF(ISNUMBER(Q26),N26-Q26,"N/D") -> -56951926 | S26: =I1509 -> 4327677.9 | T26: =IFERROR(INDEX(Intereses_x_Obligacion!$I:$I,MATCH("BOG-L556449064",Intereses_x_Obligacion!$A:$A,0)),"N/D") -> 28058555 | U26: =IF(ISNUMBER(T26),T26-S26,"N/D") -> 23730877 | V26: =MAX(I1510,0) -> 94380151 | W26: =IF(COUNTIF(Detalle_62!$C$14:$C$35,A26)>0,SUMIFS(Detalle_62!$M$14:$M$35,Detalle_62!$C$14:$C$35,A26),"No está") -> 1.7563157e+08 | X26: =IF(ISNUMBER(W26),V26-W26,"N/A") -> -81251418 | Y26: =I1511 -> 4.4703484e-08 | Z26: N/A | AA26: N/A | AB26: Tabla a tasa fija con TIR muy baja (0,59% trimestral) y capital acelerado: saldo $57 MM por debajo del banco.
A27: BOG-L556449288 | B27: 9299 | C27: A16-9299 | D27: BANCO DE BOGOTA | E27: 556449288 | F27: Leasing | G27: =C1550 -> 569902000 | H27: =C1551 -> 44949 | I27: =C1552 -> 28 TRIMESTRES – DTF+3,57% | J27: =IF(ISNUMBER(C1553),C1553,"Por fila") -> 0.036728133 | K27: =IFERROR(C1554,"N/A") -> 0.036728133 | L27: =IF(AND(ISNUMBER(J27),ISNUMBER(K27)),(K27-J27)*10000,"N/A") -> -4.9960036e-12 | M27: =I1550 -> 46226 | N27: =I1551 -> 3.8264924e+08 | O27: =IF(COUNTIF(Detalle_62!$C$14:$C$35,A27)>0,SUMIFS(Detalle_62!$F$14:$F$35,Detalle_62!$C$14:$C$35,A27),"No está") -> 3.8264924e+08 | P27: =IF(ISNUMBER(O27),N27-O27,"N/A") -> 0 | Q27: =IFERROR(INDEX(Pruebas_Auditoria!$L$144:$L$183,MATCH("BOG-L556449288",Pruebas_Auditoria!$A$144:$A$183,0)),"N/D") -> 3.9619394e+08 | R27: =IF(ISNUMBER(Q27),N27-Q27,"N/D") -> -13544703 | S27: =I1553 -> 46536705 | T27: =IFERROR(INDEX(Intereses_x_Obligacion!$I:$I,MATCH("BOG-L556449288",Intereses_x_Obligacion!$A:$A,0)),"N/D") -> 30902950 | U27: =IF(ISNUMBER(T27),T27-S27,"N/D") -> -15633755 | V27: =MAX(I1554,0) -> 89056070 | W27: =IF(COUNTIF(Detalle_62!$C$14:$C$35,A27)>0,SUMIFS(Detalle_62!$M$14:$M$35,Detalle_62!$C$14:$C$35,A27),"No está") -> 1.7563157e+08 | X27: =IF(ISNUMBER(W27),V27-W27,"N/A") -> -86575499 | Y27: =I1555 -> 1.4901161e-08 | Z27: N/A | AA27: N/A | AB27: Tabla a tasa fija; el banco liquida DTF variable: saldo certificado mayor que el de la tabla.
A28: BOG-L557285005 | B28: 5005 | C28: A17-5005 | D28: BANCO DE BOGOTA | E28: 557285005 | F28: Leasing | G28: =C1594 -> 1622075804 | H28: =C1595 -> 44764 | I28: =C1596 -> 24 TRIMESTRES – IBR(3M)+3,78% | J28: =IF(ISNUMBER(C1597),C1597,"Por fila") -> 0.031890496 | K28: =IFERROR(C1598,"N/A") -> 0.031890496 | L28: =IF(AND(ISNUMBER(J28),ISNUMBER(K28)),(K28-J28)*10000,"N/A") -> 0 | M28: =I1594 -> 46225 | N28: =I1595 -> 9.6862047e+08 | O28: =IF(COUNTIF(Detalle_62!$C$14:$C$35,A28)>0,SUMIFS(Detalle_62!$F$14:$F$35,Detalle_62!$C$14:$C$35,A28),"No está") -> 9.6862047e+08 | P28: =IF(ISNUMBER(O28),N28-O28,"N/A") -> 0 | Q28: =IFERROR(INDEX(Pruebas_Auditoria!$L$144:$L$183,MATCH("BOG-L557285005",Pruebas_Auditoria!$A$144:$A$183,0)),"N/D") -> 9.8424689e+08 | R28: =IF(ISNUMBER(Q28),N28-Q28,"N/D") -> -15626414 | S28: =I1597 -> 1.0472844e+08 | T28: =IFERROR(INDEX(Intereses_x_Obligacion!$I:$I,MATCH("BOG-L557285005",Intereses_x_Obligacion!$A:$A,0)),"N/D") -> 89512386 | U28: =IF(ISNUMBER(T28),T28-S28,"N/D") -> -15216056 | V28: =MAX(I1598,0) -> 2.7853765e+08 | W28: =IF(COUNTIF(Detalle_62!$C$14:$C$35,A28)>0,SUMIFS(Detalle_62!$M$14:$M$35,Detalle_62!$C$14:$C$35,A28),"No está") -> 722980190 | X28: =IF(ISNUMBER(W28),V28-W28,"N/A") -> -4.4444254e+08 | Y28: =I1599 -> 1.937151e-07 | Z28: N/A | AA28: N/A | AB28: Tabla a tasa fija; el banco liquida IBR 3M variable: saldo certificado mayor que el de la tabla.
A29: POP-631309940 | B29: P-9940 | C29: A18-P-9940 | D29: BANCO POPULAR | E29: 631309940-2 | F29: Crédito | G29: =C1634 -> 2300000000 | H29: =C1635 -> 44547 | I29: =C1636 -> 60 meses – IBR 3MESES +2,4 | J29: =IF(ISNUMBER(C1637),C1637,"Por fila") -> Por fila | K29: =IFERROR(C1638,"N/A") -> N/A | L29: =IF(AND(ISNUMBER(J29),ISNUMBER(K29)),(K29-J29)*10000,"N/A") -> N/A | M29: =I1634 -> 46220 | N29: =I1635 -> 287500000 | O29: =IF(COUNTIF(Detalle_62!$C$14:$C$35,A29)>0,SUMIFS(Detalle_62!$F$14:$F$35,Detalle_62!$C$14:$C$35,A29),"No está") -> 287500000 | P29: =IF(ISNUMBER(O29),N29-O29,"N/A") -> 0 | Q29: =IFERROR(INDEX(Pruebas_Auditoria!$L$144:$L$183,MATCH("POP-631309940",Pruebas_Auditoria!$A$144:$A$183,0)),"N/D") -> 287500000 | R29: =IF(ISNUMBER(Q29),N29-Q29,"N/D") -> 0 | S29: =I1637 -> 36715667 | T29: =IFERROR(INDEX(Intereses_x_Obligacion!$I:$I,MATCH("POP-631309940",Intereses_x_Obligacion!$A:$A,0)),"N/D") -> 34304862 | U29: =IF(ISNUMBER(T29),T29-S29,"N/D") -> -2410804.7 | V29: =MAX(I1638,0) -> 287500000 | W29: =IF(COUNTIF(Detalle_62!$C$14:$C$35,A29)>0,SUMIFS(Detalle_62!$M$14:$M$35,Detalle_62!$C$14:$C$35,A29),"No está") -> 575000000 | X29: =IF(ISNUMBER(W29),V29-W29,"N/A") -> -287500000 | Y29: =I1639 -> 0 | Z29: 2.8714872e+08 | AA29: =IF(ISNUMBER(Z29),Z29-N29,"N/A") -> -351282.59 | AB29: Capital trimestral $143,75 MM coincide con lo pagado; vence 17-dic-26 (todo corriente).
A30: BBVA-9600277262 | B30: V-7262 | C30: A19-V-7262 | D30: BBVA | E30: 9600277262 | F30: Crédito | G30: =C1710 -> 4700000000 | H30: =C1711 -> 46002 | I30: =C1712 -> 6 meses – IBR 3 MESES + 0,95% | J30: =IF(ISNUMBER(C1713),C1713,"Por fila") -> Por fila | K30: =IFERROR(C1714,"N/A") -> 0.0099264868 | L30: =IF(AND(ISNUMBER(J30),ISNUMBER(K30)),(K30-J30)*10000,"N/A") -> N/A | M30: =I1710 -> 46184 | N30: =I1711 -> 0 | O30: =IF(COUNTIF(Detalle_62!$C$14:$C$35,A30)>0,SUMIFS(Detalle_62!$F$14:$F$35,Detalle_62!$C$14:$C$35,A30),"No está") -> No está | P30: =IF(ISNUMBER(O30),N30-O30,"N/A") -> N/A | Q30: =IFERROR(INDEX(Pruebas_Auditoria!$L$144:$L$183,MATCH("BBVA-9600277262",Pruebas_Auditoria!$A$144:$A$183,0)),"N/D") -> N/D | R30: =IF(ISNUMBER(Q30),N30-Q30,"N/D") -> N/D | S30: =I1713 -> 2.8017092e+08 | T30: =IFERROR(INDEX(Intereses_x_Obligacion!$I:$I,MATCH("BBVA-9600277262",Intereses_x_Obligacion!$A:$A,0)),"N/D") -> N/D | U30: =IF(ISNUMBER(T30),T30-S30,"N/D") -> N/D | V30: =MAX(I1714,0) -> 0 | W30: =IF(COUNTIF(Detalle_62!$C$14:$C$35,A30)>0,SUMIFS(Detalle_62!$M$14:$M$35,Detalle_62!$C$14:$C$35,A30),"No está") -> No está | X30: =IF(ISNUMBER(W30),V30-W30,"N/A") -> N/A | Y30: =I1715 -> 0 | Z30: 0 | AA30: =IF(ISNUMBER(Z30),Z30-N30,"N/A") -> 0 | AB30: Tabla del crédito anterior (11-dic-25 a 11-jun-26). No hay tabla del crédito renovado el 30-jun-26 (glosa 'crédito 0141').
A31: BCL-1260105867 | B31: BC-5867 | C31: A20-BC-5867 | D31: BANCOLOMBIA | E31: 1260105867 | F31: Crédito | G31: =C1732 -> 5000000000 | H31: =C1733 -> 45768 | I31: =C1734 -> 36 meses – IBR 3 MESES + 1,5% | J31: =IF(ISNUMBER(C1735),C1735,"Por fila") -> Por fila | K31: =IFERROR(C1736,"N/A") -> 0.0099893752 | L31: =IF(AND(ISNUMBER(J31),ISNUMBER(K31)),(K31-J31)*10000,"N/A") -> N/A | M31: =I1732 -> 46224 | N31: =I1733 -> 3.3333333e+09 | O31: =IF(COUNTIF(Detalle_62!$C$14:$C$35,A31)>0,SUMIFS(Detalle_62!$F$14:$F$35,Detalle_62!$C$14:$C$35,A31),"No está") -> 3.3333333e+09 | P31: =IF(ISNUMBER(O31),N31-O31,"N/A") -> 0 | Q31: =IFERROR(INDEX(Pruebas_Auditoria!$L$144:$L$183,MATCH("BCL-1260105867",Pruebas_Auditoria!$A$144:$A$183,0)),"N/D") -> 3333333334 | R31: =IF(ISNUMBER(Q31),N31-Q31,"N/D") -> -0.66666698 | S31: =I1735 -> 3.1140278e+08 | T31: =IFERROR(INDEX(Intereses_x_Obligacion!$I:$I,MATCH("BCL-1260105867",Intereses_x_Obligacion!$A:$A,0)),"N/D") -> 287833704 | U31: =IF(ISNUMBER(T31),T31-S31,"N/D") -> -23569074 | V31: =MAX(I1736,0) -> 1.6666667e+09 | W31: =IF(COUNTIF(Detalle_62!$C$14:$C$35,A31)>0,SUMIFS(Detalle_62!$M$14:$M$35,Detalle_62!$C$14:$C$35,A31),"No está") -> 1.6666667e+09 | X31: =IF(ISNUMBER(W31),V31-W31,"N/A") -> -0.0033330917 | Y31: =I1737 -> 0 | Z31: 3.3821184e+09 | AA31: =IF(ISNUMBER(Z31),Z31-N31,"N/A") -> 48785100 | AB31: Capital anual $1.666,7 MM; coincide con el certificado (capital vigente $3.333.333.334).
A32: BCL-L362095 | B32: 362095 | C32: A21-362095 | D32: LEASING BANCOLOMBIA S.A. | E32: 362095 | F32: Leasing | G32: =C1784 -> 561680000 | H32: =C1785 -> 45730 | I32: =C1786 -> 60 MESES – IBR TV + 2,85% | J32: =IF(ISNUMBER(C1787),C1787,"Por fila") -> 0.02145014 | K32: =IFERROR(C1788,"N/A") -> 0.025689224 | L32: =IF(AND(ISNUMBER(J32),ISNUMBER(K32)),(K32-J32)*10000,"N/A") -> 42.390836 | M32: =I1784 -> 46187 | N32: =I1785 -> 5.2451929e+08 | O32: =IF(COUNTIF(Detalle_62!$C$14:$C$35,A32)>0,SUMIFS(Detalle_62!$F$14:$F$35,Detalle_62!$C$14:$C$35,A32),"No está") -> 497241599 | P32: =IF(ISNUMBER(O32),N32-O32,"N/A") -> 27277692 | Q32: =IFERROR(INDEX(Pruebas_Auditoria!$L$144:$L$183,MATCH("BCL-L362095",Pruebas_Auditoria!$A$144:$A$183,0)),"N/D") -> 448477372 | R32: =IF(ISNUMBER(Q32),N32-Q32,"N/D") -> 76041919 | S32: =I1787 -> 20871066 | T32: =IFERROR(INDEX(Intereses_x_Obligacion!$I:$I,MATCH("BCL-L362095",Intereses_x_Obligacion!$A:$A,0)),"N/D") -> 32199918 | U32: =IF(ISNUMBER(T32),T32-S32,"N/D") -> 11328852 | V32: =MAX(I1788,0) -> 1.4864284e+08 | W32: =IF(COUNTIF(Detalle_62!$C$14:$C$35,A32)>0,SUMIFS(Detalle_62!$M$14:$M$35,Detalle_62!$C$14:$C$35,A32),"No está") -> 154259653 | X32: =IF(ISNUMBER(W32),V32-W32,"N/A") -> -5616817.5 | Y32: =I1789 -> 5.2154064e-08 | Z32: N/A | AA32: N/A | AB32: ERROR: el periodo 5 (14-jun-26) aumenta el saldo en $48,8 MM (capital negativo) y la última cuota deja saldo negativo. El detalle 62 usa el saldo de dic-25 ($497,2 MM) sin actualizar.
A33: BCL-L336817 | B33: 336817 | C33: A22-336817 | D33: LEASING BANCOLOMBIA S.A. | E33: 336817 | F33: Leasing | G33: =C1820 -> 858438452 | H33: =C1821 -> 45804 | I33: =C1822 -> 72 MESES – IBR MV + 3,2% | J33: =IF(ISNUMBER(C1823),C1823,"Por fila") -> 0.0079203502 | K33: =IFERROR(C1824,"N/A") -> N/A | L33: =IF(AND(ISNUMBER(J33),ISNUMBER(K33)),(K33-J33)*10000,"N/A") -> N/A | M33: =I1820 -> 46230 | N33: =I1821 -> 7.7008543e+08 | O33: =IF(COUNTIF(Detalle_62!$C$14:$C$35,A33)>0,SUMIFS(Detalle_62!$F$14:$F$35,Detalle_62!$C$14:$C$35,A33),"No está") -> 7.7008543e+08 | P33: =IF(ISNUMBER(O33),N33-O33,"N/A") -> 0 | Q33: =IFERROR(INDEX(Pruebas_Auditoria!$L$144:$L$183,MATCH("BCL-L336817",Pruebas_Auditoria!$A$144:$A$183,0)),"N/D") -> 787729700 | R33: =IF(ISNUMBER(Q33),N33-Q33,"N/D") -> -17644275 | S33: =I1823 -> 44946958 | T33: =IFERROR(INDEX(Intereses_x_Obligacion!$I:$I,MATCH("BCL-L336817",Intereses_x_Obligacion!$A:$A,0)),"N/D") -> 28583500 | U33: =IF(ISNUMBER(T33),T33-S33,"N/D") -> -16363458 | V33: =MAX(I1824,0) -> 1.3031695e+08 | W33: =IF(COUNTIF(Detalle_62!$C$14:$C$35,A33)>0,SUMIFS(Detalle_62!$M$14:$M$35,Detalle_62!$C$14:$C$35,A33),"No está") -> 206513651 | X33: =IF(ISNUMBER(W33),V33-W33,"N/A") -> -76196703 | Y33: =I1825 -> 6.7055225e-08 | Z33: N/A | AA33: N/A | AB33: Tabla a tasa fija; detalle 62 = saldo de la tabla. Sin extracto 2026.
A34: BCL-L331330 | B34: 331330 | C34: A23-331330 | D34: LEASING BANCOLOMBIA S.A. | E34: 331330 | F34: Leasing | G34: =C1908 -> 915429932 | H34: =C1909 -> 45133 | I34: =C1910 -> 60 Meses – IBR+3,75% | J34: =IF(ISNUMBER(C1911),C1911,"Por fila") -> 0.02539371 | K34: =IFERROR(C1912,"N/A") -> 0.022892936 | L34: =IF(AND(ISNUMBER(J34),ISNUMBER(K34)),(K34-J34)*10000,"N/A") -> -25.00774 | M34: =I1908 -> 46229 | N34: =I1909 -> 503693510 | O34: =IF(COUNTIF(Detalle_62!$C$14:$C$35,A34)>0,SUMIFS(Detalle_62!$F$14:$F$35,Detalle_62!$C$14:$C$35,A34),"No está") -> 503693510 | P34: =IF(ISNUMBER(O34),N34-O34,"N/A") -> 0 | Q34: =IFERROR(INDEX(Pruebas_Auditoria!$L$144:$L$183,MATCH("BCL-L331330",Pruebas_Auditoria!$A$144:$A$183,0)),"N/D") -> 488525504 | R34: =IF(ISNUMBER(Q34),N34-Q34,"N/D") -> 15168006 | S34: =I1911 -> 99905793 | T34: =IFERROR(INDEX(Intereses_x_Obligacion!$I:$I,MATCH("BCL-L331330",Intereses_x_Obligacion!$A:$A,0)),"N/D") -> 26060708 | U34: =IF(ISNUMBER(T34),T34-S34,"N/D") -> -73845085 | V34: =MAX(I1912,0) -> 175036572 | W34: =IF(COUNTIF(Detalle_62!$C$14:$C$35,A34)>0,SUMIFS(Detalle_62!$M$14:$M$35,Detalle_62!$C$14:$C$35,A34),"No está") -> 388559429 | X34: =IF(ISNUMBER(W34),V34-W34,"N/A") -> -213522857 | Y34: =I1913 -> 0 | Z34: N/A | AA34: N/A | AB34: Tabla con amortización de capital constante $14.586.381, pero desde feb-26 se paga $17.114.382 (mayor): la tabla no refleja los pagos reales.
A35: DYP-482800190700 | B35: DD-0709 | C35: A24-DD-0709 | D35: DAVIVIENDA DYPSIS | E35: 7000482800190700 | F35: Crédito | G35: =C1984 -> 72300000000 | H35: =C1985 -> 45807 | I35: =C1986 -> 24 meses – IBR 3 MESES + 2,2% | J35: =IF(ISNUMBER(C1987),C1987,"Por fila") -> Por fila | K35: =IFERROR(C1988,"N/A") -> 0.010688955 | L35: =IF(AND(ISNUMBER(J35),ISNUMBER(K35)),(K35-J35)*10000,"N/A") -> N/A | M35: =I1984 -> 46233 | N35: =I1985 -> 72300000000 | O35: =IF(COUNTIF(Detalle_62!$C$14:$C$35,A35)>0,SUMIFS(Detalle_62!$F$14:$F$35,Detalle_62!$C$14:$C$35,A35),"No está") -> No está | P35: =IF(ISNUMBER(O35),N35-O35,"N/A") -> N/A | Q35: =IFERROR(INDEX(Pruebas_Auditoria!$L$144:$L$183,MATCH("DYP-482800190700",Pruebas_Auditoria!$A$144:$A$183,0)),"N/D") -> N/D | R35: =IF(ISNUMBER(Q35),N35-Q35,"N/D") -> N/D | S35: =I1987 -> 5585235250 | T35: =IFERROR(INDEX(Intereses_x_Obligacion!$I:$I,MATCH("DYP-482800190700",Intereses_x_Obligacion!$A:$A,0)),"N/D") -> N/D | U35: =IF(ISNUMBER(T35),T35-S35,"N/D") -> N/D | V35: =MAX(I1988,0) -> 72300000000 | W35: =IF(COUNTIF(Detalle_62!$C$14:$C$35,A35)>0,SUMIFS(Detalle_62!$M$14:$M$35,Detalle_62!$C$14:$C$35,A35),"No está") -> No está | X35: =IF(ISNUMBER(W35),V35-W35,"N/A") -> N/A | Y35: =I1989 -> 0 | Z35: 7.2948852e+10 | AA35: =IF(ISNUMBER(Z35),Z35-N35,"N/A") -> 6.4885162e+08 | AB35: Crédito Davivienda DYPSIS $72.300 MM (30-may-25 a 28-may-27) incluido en el archivo de tablas pero NO registrado en el mayor de Guaicaramo. Confirmar titular, vinculación y garantías otorgadas.
